Workbook
Name year: 'Conversion and emission factors'!$C$2
Name year: #REF!

Sheet QAQC
B2: Quality Assurance and Quality Control
B4: Workbook Information
B5: File Name: | C5: Conversion and emission factors for publication
B6: Description of file: | C6: Energy conversion and emission factors for publication on SEAI website.
B7: Status: (Draft/ Ongoing /Final) | C7: Ongoing
B10: Versions
C11: Date | D11: High-Level Details
B12: V1.0 | C12: 45089 | D12: New file created for 2022 data
B13: V1.1 | C13: 45201 | D13: Updated 2022 values for electricity, natural gas, petroleum coke and milled peat. Expanded explanatary notes.
B14: V1.2 | C14: 45293 | D14: Updated 2022 values for blended petrol and diesel. Updated fuel oil density. Added biojet HVO.
B15: V1.3 | C15: 45443 | D15: Added 2023 values.
B16: V1.4 | C16: 45740 | D16: - Updated 2023 values for electricity, natural gas, blended road petrol & diesel. - Density values for biodiesel HVO and CHVO have been updated to match those provided in the EU's recast Renewable Energy Directive.
B17: V1.5 | C17: 45827 | D17: - 2024 values added - 'Electricity generation' factor relabelled to 'Gross electricity generation' and associated notes updated for clarity. - Biodiesel ME emission factors updated, based on 5.4% fossil carbon as per EPA's National Inventory Submission 2025
B18: V1.6 | C18: 46008 | D18: - 2024 CO2 factors updated for natural gas and petroleum coke - Additional notes added for milled peat
B19: V1.7 | C19: 46192 | D19: - 2025 values added - Updates to Electricity Consumption and Gross Electricity Supply CO2 timeseries
B21: QA Checking
B22: Author Name: | C22: Energy Statistics Team
B23: Contact: | C23: epssu@seai.ie

Sheet Conversion and emission factors
B2: Energy conversion and emission factors | D2: 2025
B3: Unless otherwise stated, all values are based on net calorific value (NCV).
B5: Comments
B6: - The tables below provide the latest conversion and emission factors for common fuel and energy types.
B7: - Some factors change over time as fuel properties, biofuel contents or electricity generation mix change.
B8: - The 'timeseries' worksheets provide historical annual factors and some additional explanation of the factors.
B10: Notes on biomass fuels, bioliquids & biofuel
B11: - The net emission of CO2 from the combustion of biogenic carbon in sustainable biomass fuel (incl. solid biomass, biofuel, bioliquid and biogas) is considered to be zero, as it is assumed that the biomass itself absorbs an equal amount of CO2 during growth as is emitted during combustion.
B12: - Where biomass fuel is not sustainably produced, CO2 emissions from combustion should be counted. This is consistent with guidelines for greenhouse gas reporting, such as the IPCC 2006 Guideline for National Greeenhouse Gas Inventories & 2019 refinement and EU Emission Trading System.
B13: - Biodiesel methyl ester (ME) emission factor is based on a fossil carbon content of 5.4%, as per EPA's National Inventory Submissions 2025.
B15: Colour coding
B16: Value is typically constant from year to year.
B17: Value typically changes on an annual basis.
B19: Liquid | C19: Energy content | F19: Emission factor | J19: Density | K19: Specific vol. | L19: PE factor | M19: Note | N19: Year
C20: toe/t | D20: MJ/kg | E20: MJ/l | F20: gCO2/kWh | G20: gCO2/MJ | H20: kgCO2/kg | I20: kgCO2/l | J20: kg/m^3 | K20: l/t | L20: -
B21: Petroleum
B22: Crude oil | C22: =D22*1000/41868 -> 1.0226 | D22: =INDEX('Energy content timeseries'!$13:$61,MATCH('Conversion and emission factors'!$B22,'Energy content timeseries'!$B$13:$B$61,0),MATCH('Conversion and emission factors'!$N22,'Energy content timeseries'!$13:$13,0)) -> 42.814217 | E22: =D22*J22/1000 -> 40.125789 | F22: =INDEX('Emission factors timeseries'!$22:$71,MATCH($B22,'Emission factors timeseries'!$B$22:$B$71,0),MATCH($N22,'Emission factors timeseries'!$21:$21,0)) -> 264 | G22: =F22/3.6 -> 73.333333 | H22: =G22*D22/1000 -> 3.1397092 | I22: =H22*J22/1000 -> 2.9425579 | J22: =INDEX('Density timeseries'!$6:$48,MATCH($B22,'Density timeseries'!$B$6:$B$48,0),MATCH($N22,'Density timeseries'!$5:$5,0)) -> 937.20712 | K22: =10^6/J22 -> 1067 | L22: =INDEX('Primary energy timeseries'!$14:$63,MATCH($B22,'Primary energy timeseries'!$B$14:$B$63,0),MATCH("Default value",'Primary energy timeseries'!$13:$13,0)) -> - | N22: =$D$2 -> 2025
B23: Gasoline / petrol (100% petroleum) | C23: =D23*1000/41868 -> 1.065 | D23: =INDEX('Energy content timeseries'!$13:$61,MATCH('Conversion and emission factors'!$B23,'Energy content timeseries'!$B$13:$B$61,0),MATCH('Conversion and emission factors'!$N23,'Energy content timeseries'!$13:$13,0)) -> 44.58942 | E23: =D23*J23/1000 -> 33.0292 | F23: =INDEX('Emission factors timeseries'!$22:$71,MATCH($B23,'Emission factors timeseries'!$B$22:$B$71,0),MATCH($N23,'Emission factors timeseries'!$21:$21,0)) -> 251.856 | G23: =F23/3.6 -> 69.96 | H23: =G23*D23/1000 -> 3.1194758 | I23: =H23*J23/1000 -> 2.3107228 | J23: =INDEX('Density timeseries'!$6:$48,MATCH($B23,'Density timeseries'!$B$6:$B$48,0),MATCH($N23,'Density timeseries'!$5:$5,0)) -> 740.74074 | K23: =10^6/J23 -> 1350 | L23: =INDEX('Primary energy timeseries'!$14:$63,MATCH($B23,'Primary energy timeseries'!$B$14:$B$63,0),MATCH("Default value",'Primary energy timeseries'!$13:$13,0)) -> 1.1 | N23: =$D$2 -> 2025
B24: Kerosene | C24: =D24*1000/41868 -> 1.0556 | D24: =INDEX('Energy content timeseries'!$13:$61,MATCH('Conversion and emission factors'!$B24,'Energy content timeseries'!$B$13:$B$61,0),MATCH('Conversion and emission factors'!$N24,'Energy content timeseries'!$13:$13,0)) -> 44.195861 | E24: =D24*J24/1000 -> 35.356689 | F24: =INDEX('Emission factors timeseries'!$22:$71,MATCH($B24,'Emission factors timeseries'!$B$22:$B$71,0),MATCH($N24,'Emission factors timeseries'!$21:$21,0)) -> 257.004 | G24: =F24/3.6 -> 71.39 | H24: =G24*D24/1000 -> 3.1551425 | I24: =H24*J24/1000 -> 2.524114 | J24: =INDEX('Density timeseries'!$6:$48,MATCH($B24,'Density timeseries'!$B$6:$B$48,0),MATCH($N24,'Density timeseries'!$5:$5,0)) -> 800 | K24: =10^6/J24 -> 1250 | L24: =INDEX('Primary energy timeseries'!$14:$63,MATCH($B24,'Primary energy timeseries'!$B$14:$B$63,0),MATCH("Default value",'Primary energy timeseries'!$13:$13,0)) -> 1.1 | N24: =$D$2 -> 2025
B25: Jet Kerosene | C25: =D25*1000/41868 -> 1.0533 | D25: =INDEX('Energy content timeseries'!$13:$61,MATCH('Conversion and emission factors'!$B25,'Energy content timeseries'!$B$13:$B$61,0),MATCH('Conversion and emission factors'!$N25,'Energy content timeseries'!$13:$13,0)) -> 44.099564 | E25: =D25*J25/1000 -> 35.279652 | F25: =INDEX('Emission factors timeseries'!$22:$71,MATCH($B25,'Emission factors timeseries'!$B$22:$B$71,0),MATCH($N25,'Emission factors timeseries'!$21:$21,0)) -> 257.004 | G25: =F25/3.6 -> 71.39 | H25: =G25*D25/1000 -> 3.1482679 | I25: =H25*J25/1000 -> 2.5186143 | J25: =INDEX('Density timeseries'!$6:$48,MATCH($B25,'Density timeseries'!$B$6:$B$48,0),MATCH($N25,'Density timeseries'!$5:$5,0)) -> 800 | K25: =10^6/J25 -> 1250 | L25: =INDEX('Primary energy timeseries'!$14:$63,MATCH($B25,'Primary energy timeseries'!$B$14:$B$63,0),MATCH("Default value",'Primary energy timeseries'!$13:$13,0)) -> 1.1 | N25: =$D$2 -> 2025
B26: Diesel / gasoil (100% petroleum) | C26: =D26*1000/41868 -> 1.0344 | D26: =INDEX('Energy content timeseries'!$13:$61,MATCH('Conversion and emission factors'!$B26,'Energy content timeseries'!$B$13:$B$61,0),MATCH('Conversion and emission factors'!$N26,'Energy content timeseries'!$13:$13,0)) -> 43.308259 | E26: =D26*J26/1000 -> 36.595479 | F26: =INDEX('Emission factors timeseries'!$22:$71,MATCH($B26,'Emission factors timeseries'!$B$22:$B$71,0),MATCH($N26,'Emission factors timeseries'!$21:$21,0)) -> 263.868 | G26: =F26/3.6 -> 73.296667 | H26: =G26*D26/1000 -> 3.174351 | I26: =H26*J26/1000 -> 2.6823266 | J26: =INDEX('Density timeseries'!$6:$48,MATCH($B26,'Density timeseries'!$B$6:$B$48,0),MATCH($N26,'Density timeseries'!$5:$5,0)) -> 845 | K26: =10^6/J26 -> 1183.432 | L26: =INDEX('Primary energy timeseries'!$14:$63,MATCH($B26,'Primary energy timeseries'!$B$14:$B$63,0),MATCH("Default value",'Primary energy timeseries'!$13:$13,0)) -> 1.1 | N26: =$D$2 -> 2025
B27: Residual fuel oil / fuel oil | C27: =D27*1000/41868 -> 0.9849 | D27: =INDEX('Energy content timeseries'!$13:$61,MATCH('Conversion and emission factors'!$B27,'Energy content timeseries'!$B$13:$B$61,0),MATCH('Conversion and emission factors'!$N27,'Energy content timeseries'!$13:$13,0)) -> 41.235793 | E27: =D27*J27/1000 -> 38.828431 | F27: =INDEX('Emission factors timeseries'!$22:$71,MATCH($B27,'Emission factors timeseries'!$B$22:$B$71,0),MATCH($N27,'Emission factors timeseries'!$21:$21,0)) -> 273.636 | G27: =F27/3.6 -> 76.01 | H27: =G27*D27/1000 -> 3.1343326 | I27: =H27*J27/1000 -> 2.951349 | J27: =INDEX('Density timeseries'!$6:$48,MATCH($B27,'Density timeseries'!$B$6:$B$48,0),MATCH($N27,'Density timeseries'!$5:$5,0)) -> 941.61959 | K27: =10^6/J27 -> 1062 | L27: =INDEX('Primary energy timeseries'!$14:$63,MATCH($B27,'Primary energy timeseries'!$B$14:$B$63,0),MATCH("Default value",'Primary energy timeseries'!$13:$13,0)) -> 1.1 | N27: =$D$2 -> 2025
B28: LPG | C28: =D28*1000/41868 -> 1.1263 | D28: =INDEX('Energy content timeseries'!$13:$61,MATCH('Conversion and emission factors'!$B28,'Energy content timeseries'!$B$13:$B$61,0),MATCH('Conversion and emission factors'!$N28,'Energy content timeseries'!$13:$13,0)) -> 47.155928 | E28: =D28*J28/1000 -> 24.624506 | F28: =INDEX('Emission factors timeseries'!$22:$71,MATCH($B28,'Emission factors timeseries'!$B$22:$B$71,0),MATCH($N28,'Emission factors timeseries'!$21:$21,0)) -> 229.284 | G28: =F28/3.6 -> 63.69 | H28: =G28*D28/1000 -> 3.0033611 | I28: =H28*J28/1000 -> 1.5683348 | J28: =INDEX('Density timeseries'!$6:$48,MATCH($B28,'Density timeseries'!$B$6:$B$48,0),MATCH($N28,'Density timeseries'!$5:$5,0)) -> 522.19321 | K28: =10^6/J28 -> 1915 | L28: =INDEX('Primary energy timeseries'!$14:$63,MATCH($B28,'Primary energy timeseries'!$B$14:$B$63,0),MATCH("Default value",'Primary energy timeseries'!$13:$13,0)) -> 1.1 | M28: Assumes a mixture of 70% propane & 30% butane by mass | N28: =$D$2 -> 2025
B30: Biofuel / bioliquid
B31: Bioethanol | C31: =D31*1000/41868 -> 0.63294163 | D31: =INDEX('Energy content timeseries'!$13:$61,MATCH('Conversion and emission factors'!$B31,'Energy content timeseries'!$B$13:$B$61,0),MATCH('Conversion and emission factors'!$N31,'Energy content timeseries'!$13:$13,0)) -> 26.5 | E31: =D31*J31/1000 -> 21.2 | F31: =INDEX('Emission factors timeseries'!$22:$71,MATCH($B31,'Emission factors timeseries'!$B$22:$B$71,0),MATCH($N31,'Emission factors timeseries'!$21:$21,0)) -> - | G31: - | H31: - | I31: - | J31: =INDEX('Density timeseries'!$6:$48,MATCH($B31,'Density timeseries'!$B$6:$B$48,0),MATCH($N31,'Density timeseries'!$5:$5,0)) -> 800 | K31: =10^6/J31 -> 1250 | L31: =INDEX('Primary energy timeseries'!$14:$63,MATCH($B31,'Primary energy timeseries'!$B$14:$B$63,0),MATCH("Default value",'Primary energy timeseries'!$13:$13,0)) -> 1.1 | N31: =$D$2 -> 2025
B32: Biodiesel ME | C32: =D32*1000/41868 -> 0.8902438 | D32: =INDEX('Energy content timeseries'!$13:$61,MATCH('Conversion and emission factors'!$B32,'Energy content timeseries'!$B$13:$B$61,0),MATCH('Conversion and emission factors'!$N32,'Energy content timeseries'!$13:$13,0)) -> 37.272727 | E32: =D32*J32/1000 -> 32.8 | F32: =INDEX('Emission factors timeseries'!$22:$71,MATCH($B32,'Emission factors timeseries'!$B$22:$B$71,0),MATCH($N32,'Emission factors timeseries'!$21:$21,0)) -> 14.629785 | G32: =F32/3.6 -> 4.0638293 | H32: =G32*D32/1000 -> 0.15147 | I32: =H32*J32/1000 -> 0.1332936 | J32: =INDEX('Density timeseries'!$6:$48,MATCH($B32,'Density timeseries'!$B$6:$B$48,0),MATCH($N32,'Density timeseries'!$5:$5,0)) -> 880 | K32: =10^6/J32 -> 1136.3636 | L32: =INDEX('Primary energy timeseries'!$14:$63,MATCH($B32,'Primary energy timeseries'!$B$14:$B$63,0),MATCH("Default value",'Primary energy timeseries'!$13:$13,0)) -> 1.1 | M32: Methyl ester; based on 5.4% fossil carbon | N32: =$D$2 -> 2025
B33: Biodiesel HVO | C33: =D33*1000/41868 -> 1.0509219 | D33: =INDEX('Energy content timeseries'!$13:$61,MATCH('Conversion and emission factors'!$B33,'Energy content timeseries'!$B$13:$B$61,0),MATCH('Conversion and emission factors'!$N33,'Energy content timeseries'!$13:$13,0)) -> 44 | E33: =D33*J33/1000 -> 34 | F33: =INDEX('Emission factors timeseries'!$22:$71,MATCH($B33,'Emission factors timeseries'!$B$22:$B$71,0),MATCH($N33,'Emission factors timeseries'!$21:$21,0)) -> - | G33: - | H33: - | I33: - | J33: =INDEX('Density timeseries'!$6:$48,MATCH($B33,'Density timeseries'!$B$6:$B$48,0),MATCH($N33,'Density timeseries'!$5:$5,0)) -> 772.72727 | K33: =10^6/J33 -> 1294.1176 | L33: =INDEX('Primary energy timeseries'!$14:$63,MATCH($B33,'Primary energy timeseries'!$B$14:$B$63,0),MATCH("Default value",'Primary energy timeseries'!$13:$13,0)) -> 1.1 | M33: Hydrotreated vegetable oil | N33: =$D$2 -> 2025
B34: Biodiesel CHVO | C34: =D34*1000/41868 -> 1.0270374 | D34: =INDEX('Energy content timeseries'!$13:$61,MATCH('Conversion and emission factors'!$B34,'Energy content timeseries'!$B$13:$B$61,0),MATCH('Conversion and emission factors'!$N34,'Energy content timeseries'!$13:$13,0)) -> 43 | E34: =D34*J34/1000 -> 36 | F34: =INDEX('Emission factors timeseries'!$22:$71,MATCH($B34,'Emission factors timeseries'!$B$22:$B$71,0),MATCH($N34,'Emission factors timeseries'!$21:$21,0)) -> - | G34: - | H34: - | I34: - | J34: =INDEX('Density timeseries'!$6:$48,MATCH($B34,'Density timeseries'!$B$6:$B$48,0),MATCH($N34,'Density timeseries'!$5:$5,0)) -> 837.2093 | K34: =10^6/J34 -> 1194.4444 | L34: =INDEX('Primary energy timeseries'!$14:$63,MATCH($B34,'Primary energy timeseries'!$B$14:$B$63,0),MATCH("Default value",'Primary energy timeseries'!$13:$13,0)) -> 1.1 | M34: Co-processed hydrotreated vegetable oil | N34: =$D$2 -> 2025
B35: Biopropane | C35: =D35*1000/41868 -> 1.0986911 | D35: =INDEX('Energy content timeseries'!$13:$61,MATCH('Conversion and emission factors'!$B35,'Energy content timeseries'!$B$13:$B$61,0),MATCH('Conversion and emission factors'!$N35,'Energy content timeseries'!$13:$13,0)) -> 46 | E35: =D35*J35/1000 -> 24 | F35: =INDEX('Emission factors timeseries'!$22:$71,MATCH($B35,'Emission factors timeseries'!$B$22:$B$71,0),MATCH($N35,'Emission factors timeseries'!$21:$21,0)) -> - | G35: - | H35: - | I35: - | J35: =INDEX('Density timeseries'!$6:$48,MATCH($B35,'Density timeseries'!$B$6:$B$48,0),MATCH($N35,'Density timeseries'!$5:$5,0)) -> 521.73913 | K35: =10^6/J35 -> 1916.6667 | L35: =INDEX('Primary energy timeseries'!$14:$63,MATCH($B35,'Primary energy timeseries'!$B$14:$B$63,0),MATCH("Default value",'Primary energy timeseries'!$13:$13,0)) -> 1.1 | N35: =$D$2 -> 2025
B36: Biojet HVO | C36: =D36*1000/41868 -> 1.0509219 | D36: =INDEX('Energy content timeseries'!$13:$61,MATCH('Conversion and emission factors'!$B36,'Energy content timeseries'!$B$13:$B$61,0),MATCH('Conversion and emission factors'!$N36,'Energy content timeseries'!$13:$13,0)) -> 44 | E36: =D36*J36/1000 -> 34 | F36: =INDEX('Emission factors timeseries'!$22:$71,MATCH($B36,'Emission factors timeseries'!$B$22:$B$71,0),MATCH($N36,'Emission factors timeseries'!$21:$21,0)) -> - | G36: - | H36: - | I36: - | J36: =INDEX('Density timeseries'!$6:$48,MATCH($B36,'Density timeseries'!$B$6:$B$48,0),MATCH($N36,'Density timeseries'!$5:$5,0)) -> 772.72727 | K36: =10^6/J36 -> 1294.1176 | L36: =INDEX('Primary energy timeseries'!$14:$63,MATCH($B36,'Primary energy timeseries'!$B$14:$B$63,0),MATCH("Default value",'Primary energy timeseries'!$13:$13,0)) -> 1.1 | N36: =$D$2 -> 2025
B38: Blended petroleum & biofuel
B39: Road diesel (avg. biofuel content) | C39: =D39*1000/41868 -> 1.0258885 | D39: =INDEX('Energy content timeseries'!$13:$61,MATCH('Conversion and emission factors'!$B39,'Energy content timeseries'!$B$13:$B$61,0),MATCH('Conversion and emission factors'!$N39,'Energy content timeseries'!$13:$13,0)) -> 42.951901 | E39: =D39*J39/1000 -> 36.301159 | F39: =INDEX('Emission factors timeseries'!$22:$71,MATCH($B39,'Emission factors timeseries'!$B$22:$B$71,0),MATCH($N39,'Emission factors timeseries'!$21:$21,0)) -> 239.04139 | G39: =F39/3.6 -> 66.400387 | H39: =G39*D39/1000 -> 2.8520228 | I39: =H39*J39/1000 -> 2.410411 | J39: =INDEX('Density timeseries'!$6:$48,MATCH($B39,'Density timeseries'!$B$6:$B$48,0),MATCH($N39,'Density timeseries'!$5:$5,0)) -> 845.15839 | K39: =10^6/J39 -> 1183.2102 | L39: =INDEX('Primary energy timeseries'!$14:$63,MATCH($B39,'Primary energy timeseries'!$B$14:$B$63,0),MATCH("Default value",'Primary energy timeseries'!$13:$13,0)) -> 1.1 | M39: Average diesel-biofuel blend in 2025 | N39: =$D$2 -> 2025
B40: Road petrol (avg. biofuel content) | C40: =D40*1000/41868 -> 1.0199418 | D40: =INDEX('Energy content timeseries'!$13:$61,MATCH('Conversion and emission factors'!$B40,'Energy content timeseries'!$B$13:$B$61,0),MATCH('Conversion and emission factors'!$N40,'Energy content timeseries'!$13:$13,0)) -> 42.702923 | E40: =D40*J40/1000 -> 31.878053 | F40: =INDEX('Emission factors timeseries'!$22:$71,MATCH($B40,'Emission factors timeseries'!$B$22:$B$71,0),MATCH($N40,'Emission factors timeseries'!$21:$21,0)) -> 235.55659 | G40: =F40/3.6 -> 65.432385 | H40: =G40*D40/1000 -> 2.7941541 | I40: =H40*J40/1000 -> 2.085857 | J40: =INDEX('Density timeseries'!$6:$48,MATCH($B40,'Density timeseries'!$B$6:$B$48,0),MATCH($N40,'Density timeseries'!$5:$5,0)) -> 746.5075 | K40: =10^6/J40 -> 1339.5713 | L40: =INDEX('Primary energy timeseries'!$14:$63,MATCH($B40,'Primary energy timeseries'!$B$14:$B$63,0),MATCH("Default value",'Primary energy timeseries'!$13:$13,0)) -> 1.1 | M40: Average petrol-biofuel blend in 2025 | N40: =$D$2 -> 2025
B42: Solid | C42: Energy content | F42: Emission factor | L42: PE factor | M42: Note | N42: Year
C43: toe/t | D43: MJ/kg | F43: gCO2/kWh | G43: gCO2/MJ | H43: kgCO2/kg | L43: -
B44: Fossil fuel
B45: Petroleum coke | C45: =D45*1000/41868 -> 0.76448518 | D45: =INDEX('Energy content timeseries'!$13:$61,MATCH('Conversion and emission factors'!$B45,'Energy content timeseries'!$B$13:$B$61,0),MATCH('Conversion and emission factors'!$N45,'Energy content timeseries'!$13:$13,0)) -> 32.007466 | F45: =INDEX('Emission factors timeseries'!$22:$71,MATCH($B45,'Emission factors timeseries'!$B$22:$B$71,0),MATCH($N45,'Emission factors timeseries'!$21:$21,0)) -> 336.1168 | G45: =F45/3.6 -> 93.365777 | H45: =G45*D45/1000 -> 2.9884019 | L45: =INDEX('Primary energy timeseries'!$14:$63,MATCH($B45,'Primary energy timeseries'!$B$14:$B$63,0),MATCH("Default value",'Primary energy timeseries'!$13:$13,0)) -> 1.1 | M45: Provisional values for 2025. | N45: =$D$2 -> 2025
B46: Bituminous coal | C46: =D46*1000/41868 -> 0.665 | D46: =INDEX('Energy content timeseries'!$13:$61,MATCH('Conversion and emission factors'!$B46,'Energy content timeseries'!$B$13:$B$61,0),MATCH('Conversion and emission factors'!$N46,'Energy content timeseries'!$13:$13,0)) -> 27.84222 | F46: =INDEX('Emission factors timeseries'!$22:$71,MATCH($B46,'Emission factors timeseries'!$B$22:$B$71,0),MATCH($N46,'Emission factors timeseries'!$21:$21,0)) -> 340.56 | G46: =F46/3.6 -> 94.6 | H46: =G46*D46/1000 -> 2.633874 | L46: =INDEX('Primary energy timeseries'!$14:$63,MATCH($B46,'Primary energy timeseries'!$B$14:$B$63,0),MATCH("Default value",'Primary energy timeseries'!$13:$13,0)) -> 1.1 | N46: =$D$2 -> 2025
B47: Anthracite | C47: =D47*1000/41868 -> 0.665 | D47: =INDEX('Energy content timeseries'!$13:$61,MATCH('Conversion and emission factors'!$B47,'Energy content timeseries'!$B$13:$B$61,0),MATCH('Conversion and emission factors'!$N47,'Energy content timeseries'!$13:$13,0)) -> 27.84222 | F47: =INDEX('Emission factors timeseries'!$22:$71,MATCH($B47,'Emission factors timeseries'!$B$22:$B$71,0),MATCH($N47,'Emission factors timeseries'!$21:$21,0)) -> 353.8788 | G47: =F47/3.6 -> 98.299667 | H47: =G47*D47/1000 -> 2.7368809 | L47: =INDEX('Primary energy timeseries'!$14:$63,MATCH($B47,'Primary energy timeseries'!$B$14:$B$63,0),MATCH("Default value",'Primary energy timeseries'!$13:$13,0)) -> 1.1 | N47: =$D$2 -> 2025
B48: Lignite | C48: =D48*1000/41868 -> 0.4733016 | D48: =INDEX('Energy content timeseries'!$13:$61,MATCH('Conversion and emission factors'!$B48,'Energy content timeseries'!$B$13:$B$61,0),MATCH('Conversion and emission factors'!$N48,'Energy content timeseries'!$13:$13,0)) -> 19.816191 | F48: =INDEX('Emission factors timeseries'!$22:$71,MATCH($B48,'Emission factors timeseries'!$B$22:$B$71,0),MATCH($N48,'Emission factors timeseries'!$21:$21,0)) -> 363.594 | G48: =F48/3.6 -> 100.99833 | H48: =G48*D48/1000 -> 2.0014023 | L48: =INDEX('Primary energy timeseries'!$14:$63,MATCH($B48,'Primary energy timeseries'!$B$14:$B$63,0),MATCH("Default value",'Primary energy timeseries'!$13:$13,0)) -> 1.1 | N48: =$D$2 -> 2025
...

Sheet Energy content timeseries
B2: Energy content timeseries
B3: Unless otherwise stated, all values are based on net calorific value (NCV).
B5: Comments
B6: - The energy content of a specific quantity of fuel is termed the 'calorific value' or 'heating value'.
B7: - The calorific values below are expressed as energy per unit mass (MJ/kg) for liquid and solid fuels, and energy per unit volume (MJ/m^3) for gas.
B8: - Gross calorific value (GCV) is determined by bringing all the products of combustion back to the original pre-combustion temperature, in particular condensing any water vapour produced.
B9: - Net calorific value (NCV) is determined by subtracting the heat of vaporisation of the water vapour from the higher heating value.
B10: - Since the NCV typically represents the amount of actual usable energy, all energy quantities in Ireland’s National Energy Balance are determined on the basis of NCVs.
B11: - The differences between net and gross calorific values are typically about 5% to 6% of the gross value for solid and liquid fuels, and about 10% for natural gas.
B13: ='Conversion and emission factors'!B19 -> Liquid | C13: Unit | D13: Note | E13: 2001 | F13: =E13+1 -> 2002 | G13: =F13+1 -> 2003 | H13: =G13+1 -> 2004 | I13: =H13+1 -> 2005 | J13: =I13+1 -> 2006 | K13: =J13+1 -> 2007 | L13: =K13+1 -> 2008 | M13: =L13+1 -> 2009 | ... AC13: =AB13+1 -> 2025
B14: Petroleum
B15: Crude oil | C15: MJ/kg | E15: 42.814217 | F15: 42.814217 | G15: 42.814217 | H15: 42.814217 | I15: 42.814217 | J15: 42.814217 | K15: 42.814217 | L15: 42.814217 | M15: 42.814217 | N15: 42.814217 | O15: 42.814217 | P15: 42.814217 | Q15: 42.814217 | R15: 42.814217 | S15: 42.814217 | T15: 42.814217 | U15: 42.814217 | V15: 42.814217 | W15: 42.814217 | X15: 42.814217 | Y15: 42.814217 | Z15: 42.814217 | AA15: 42.814217 | AB15: 42.814217 | AC15: 42.814217
B16: Gasoline / petrol (100% petroleum) | C16: MJ/kg | E16: 44.58942 | F16: 44.58942 | G16: 44.58942 | H16: 44.58942 | I16: 44.58942 | J16: 44.58942 | K16: 44.58942 | L16: 44.58942 | M16: 44.58942 | N16: 44.58942 | O16: 44.58942 | P16: 44.58942 | Q16: 44.58942 | R16: 44.58942 | S16: 44.58942 | T16: 44.58942 | U16: 44.58942 | V16: 44.58942 | W16: 44.58942 | X16: 44.58942 | Y16: 44.58942 | Z16: 44.58942 | AA16: 44.58942 | AB16: 44.58942 | AC16: 44.58942
B17: Kerosene | C17: MJ/kg | E17: 44.195861 | F17: 44.195861 | G17: 44.195861 | H17: 44.195861 | I17: 44.195861 | J17: 44.195861 | K17: 44.195861 | L17: 44.195861 | M17: 44.195861 | N17: 44.195861 | O17: 44.195861 | P17: 44.195861 | Q17: 44.195861 | R17: 44.195861 | S17: 44.195861 | T17: 44.195861 | U17: 44.195861 | V17: 44.195861 | W17: 44.195861 | X17: 44.195861 | Y17: 44.195861 | Z17: 44.195861 | AA17: 44.195861 | AB17: 44.195861 | AC17: 44.195861
B18: Jet Kerosene | C18: MJ/kg | E18: 44.099564 | F18: 44.099564 | G18: 44.099564 | H18: 44.099564 | I18: 44.099564 | J18: 44.099564 | K18: 44.099564 | L18: 44.099564 | M18: 44.099564 | N18: 44.099564 | O18: 44.099564 | P18: 44.099564 | Q18: 44.099564 | R18: 44.099564 | S18: 44.099564 | T18: 44.099564 | U18: 44.099564 | V18: 44.099564 | W18: 44.099564 | X18: 44.099564 | Y18: 44.099564 | Z18: 44.099564 | AA18: 44.099564 | AB18: 44.099564 | AC18: 44.099564
B19: Diesel / gasoil (100% petroleum) | C19: MJ/kg | E19: 43.308259 | F19: 43.308259 | G19: 43.308259 | H19: 43.308259 | I19: 43.308259 | J19: 43.308259 | K19: 43.308259 | L19: 43.308259 | M19: 43.308259 | N19: 43.308259 | O19: 43.308259 | P19: 43.308259 | Q19: 43.308259 | R19: 43.308259 | S19: 43.308259 | T19: 43.308259 | U19: 43.308259 | V19: 43.308259 | W19: 43.308259 | X19: 43.308259 | Y19: 43.308259 | Z19: 43.308259 | AA19: 43.308259 | AB19: 43.308259 | AC19: 43.308259
B20: Residual fuel oil / fuel oil | C20: MJ/kg | E20: 41.235793 | F20: 41.235793 | G20: 41.235793 | H20: 41.235793 | I20: 41.235793 | J20: 41.235793 | K20: 41.235793 | L20: 41.235793 | M20: 41.235793 | N20: 41.235793 | O20: 41.235793 | P20: 41.235793 | Q20: 41.235793 | R20: 41.235793 | S20: 41.235793 | T20: 41.235793 | U20: 41.235793 | V20: 41.235793 | W20: 41.235793 | X20: 41.235793 | Y20: 41.235793 | Z20: 41.235793 | AA20: 41.235793 | AB20: 41.235793 | AC20: 41.235793
B21: LPG | C21: MJ/kg | D21: Assumes a mixture of 70% propane & 30% butane by mass | E21: 47.155928 | F21: 47.155928 | G21: 47.155928 | H21: 47.155928 | I21: 47.155928 | J21: 47.155928 | K21: 47.155928 | L21: 47.155928 | M21: 47.155928 | N21: 47.155928 | O21: 47.155928 | P21: 47.155928 | Q21: 47.155928 | R21: 47.155928 | S21: 47.155928 | T21: 47.155928 | U21: 47.155928 | V21: 47.155928 | W21: 47.155928 | X21: 47.155928 | Y21: 47.155928 | Z21: 47.155928 | AA21: 47.155928 | AB21: 47.155928 | AC21: 47.155928
B23: Biofuel / bioliquid
B24: Bioethanol | C24: MJ/kg | E24: 26.5 | F24: 26.5 | G24: 26.5 | H24: 26.5 | I24: 26.5 | J24: 26.5 | K24: 26.5 | L24: 26.5 | M24: 26.5 | N24: 26.5 | O24: 26.5 | P24: 26.5 | Q24: 26.5 | R24: 26.5 | S24: 26.5 | T24: 26.5 | U24: 26.5 | V24: 26.5 | W24: 26.5 | X24: 26.5 | Y24: 26.5 | Z24: 26.5 | AA24: 26.5 | AB24: 26.5 | AC24: 26.5
B25: Biodiesel ME | C25: MJ/kg | D25: Methyl ester | E25: 37.272727 | F25: 37.272727 | G25: 37.272727 | H25: 37.272727 | I25: 37.272727 | J25: 37.272727 | K25: 37.272727 | L25: 37.272727 | M25: 37.272727 | N25: 37.272727 | O25: 37.272727 | P25: 37.272727 | Q25: 37.272727 | R25: 37.272727 | S25: 37.272727 | T25: 37.272727 | U25: 37.272727 | V25: 37.272727 | W25: 37.272727 | X25: 37.272727 | Y25: 37.272727 | Z25: 37.272727 | AA25: 37.272727 | AB25: 37.272727 | AC25: 37.272727
B26: Biodiesel HVO | C26: MJ/kg | D26: Hydrotreated vegetable oil | R26: 44 | S26: 44 | T26: 44 | U26: 44 | V26: 44 | W26: 44 | X26: 44 | Y26: 44 | Z26: 44 | AA26: 44 | AB26: 44 | AC26: 44
B27: Biodiesel CHVO | C27: MJ/kg | D27: Co-processed hydrotreated vegetable oil | R27: 43 | S27: 43 | T27: 43 | U27: 43 | V27: 43 | W27: 43 | X27: 43 | Y27: 43 | Z27: 43 | AA27: 43 | AB27: 43 | AC27: 43
B28: Biopropane | C28: MJ/kg | R28: 46 | S28: 46 | T28: 46 | U28: 46 | V28: 46 | W28: 46 | X28: 46 | Y28: 46 | Z28: 46 | AA28: 46 | AB28: 46 | AC28: 46
B29: Biojet HVO | C29: MJ/kg | D29: Hydrotreated vegetable oil | R29: 44 | S29: 44 | T29: 44 | U29: 44 | V29: 44 | W29: 44 | X29: 44 | Y29: 44 | Z29: 44 | AA29: 44 | AB29: 44 | AC29: 44
B31: Blended petroleum & biofuel
B32: Road diesel (avg. biofuel content) | C32: MJ/kg | E32: {=_xlfn._xlws.FILTER(road_diesel_blend[Blend_mj_kg],road_diesel_blend[Year]=E$13)} -> 43.308259 | F32: {=_xlfn._xlws.FILTER(road_diesel_blend[Blend_mj_kg],road_diesel_blend[Year]=F$13)} -> 43.308259 | G32: {=_xlfn._xlws.FILTER(road_diesel_blend[Blend_mj_kg],road_diesel_blend[Year]=G$13)} -> 43.308259 | H32: {=_xlfn._xlws.FILTER(road_diesel_blend[Blend_mj_kg],road_diesel_blend[Year]=H$13)} -> 43.308259 | I32: {=_xlfn._xlws.FILTER(road_diesel_blend[Blend_mj_kg],road_diesel_blend[Year]=I$13)} -> 43.304914 | J32: {=_xlfn._xlws.FILTER(road_diesel_blend[Blend_mj_kg],road_diesel_blend[Year]=J$13)} -> 43.30251 | K32: {=_xlfn._xlws.FILTER(road_diesel_blend[Blend_mj_kg],road_diesel_blend[Year]=K$13)} -> 43.260909 | L32: {=_xlfn._xlws.FILTER(road_diesel_blend[Blend_mj_kg],road_diesel_blend[Year]=L$13)} -> 43.204412 | ... AC32: {=_xlfn._xlws.FILTER(road_diesel_blend[Blend_mj_kg],road_diesel_blend[Year]=AC$13)} -> 42.951901
B33: Road petrol (avg. biofuel content) | C33: MJ/kg | E33: {=_xlfn._xlws.FILTER(road_petrol_blend[Blend_mj_kg],road_petrol_blend[Year]=E$13)} -> 44.58942 | F33: {=_xlfn._xlws.FILTER(road_petrol_blend[Blend_mj_kg],road_petrol_blend[Year]=F$13)} -> 44.58942 | G33: {=_xlfn._xlws.FILTER(road_petrol_blend[Blend_mj_kg],road_petrol_blend[Year]=G$13)} -> 44.58942 | H33: {=_xlfn._xlws.FILTER(road_petrol_blend[Blend_mj_kg],road_petrol_blend[Year]=H$13)} -> 44.58942 | I33: {=_xlfn._xlws.FILTER(road_petrol_blend[Blend_mj_kg],road_petrol_blend[Year]=I$13)} -> 44.589281 | J33: {=_xlfn._xlws.FILTER(road_petrol_blend[Blend_mj_kg],road_petrol_blend[Year]=J$13)} -> 44.578802 | K33: {=_xlfn._xlws.FILTER(road_petrol_blend[Blend_mj_kg],road_petrol_blend[Year]=K$13)} -> 44.532881 | L33: {=_xlfn._xlws.FILTER(road_petrol_blend[Blend_mj_kg],road_petrol_blend[Year]=L$13)} -> 44.291451 | ... AC33: {=_xlfn._xlws.FILTER(road_petrol_blend[Blend_mj_kg],road_petrol_blend[Year]=AC$13)} -> 42.702923
B36: Solid | C36: Unit | D36: Note | E36: 2001 | F36: =E36+1 -> 2002 | G36: =F36+1 -> 2003 | H36: =G36+1 -> 2004 | I36: =H36+1 -> 2005 | J36: =I36+1 -> 2006 | K36: =J36+1 -> 2007 | L36: =K36+1 -> 2008 | M36: =L36+1 -> 2009 | ... AC36: =AB36+1 -> 2025
B37: Fossil fuel
B38: Petroleum coke | C38: MJ/kg | E38: 32.32575 | F38: 32.32575 | G38: 32.32575 | H38: 32.32575 | I38: 32.529 | J38: 32.363 | K38: 32.327 | L38: 32.084 | M38: 32.084 | N38: 32.084 | O38: 32.084 | P38: 32.518475 | Q38: 32.223777 | R38: 32.643604 | S38: 31.874271 | T38: 31.996363 | U38: 31.630964 | V38: 31.218005 | W38: 31.739162 | X38: 31.900761 | Y38: 32.159253 | Z38: 32.108891 | AA38: 32.089874 | AB38: 31.566386 | AC38: 32.007466
B39: Bituminous coal | C39: MJ/kg | E39: 27.84222 | F39: 27.84222 | G39: 27.84222 | H39: 27.84222 | I39: 27.84222 | J39: 27.84222 | K39: 27.84222 | L39: 27.84222 | M39: 27.84222 | N39: 27.84222 | O39: 27.84222 | P39: 27.84222 | Q39: 27.84222 | R39: 27.84222 | S39: 27.84222 | T39: 27.84222 | U39: 27.84222 | V39: 27.84222 | W39: 27.84222 | X39: 27.84222 | Y39: 27.84222 | Z39: 27.84222 | AA39: 27.84222 | AB39: 27.84222 | AC39: 27.84222
B40: Anthracite | C40: MJ/kg | E40: 27.84222 | F40: 27.84222 | G40: 27.84222 | H40: 27.84222 | I40: 27.84222 | J40: 27.84222 | K40: 27.84222 | L40: 27.84222 | M40: 27.84222 | N40: 27.84222 | O40: 27.84222 | P40: 27.84222 | Q40: 27.84222 | R40: 27.84222 | S40: 27.84222 | T40: 27.84222 | U40: 27.84222 | V40: 27.84222 | W40: 27.84222 | X40: 27.84222 | Y40: 27.84222 | Z40: 27.84222 | AA40: 27.84222 | AB40: 27.84222 | AC40: 27.84222
B41: Lignite | C41: MJ/kg | E41: 19.816191 | F41: 19.816191 | G41: 19.816191 | H41: 19.816191 | I41: 19.816191 | J41: 19.816191 | K41: 19.816191 | L41: 19.816191 | M41: 19.816191 | N41: 19.816191 | O41: 19.816191 | P41: 19.816191 | Q41: 19.816191 | R41: 19.816191 | S41: 19.816191 | T41: 19.816191 | U41: 19.816191 | V41: 19.816191 | W41: 19.816191 | X41: 19.816191 | Y41: 19.816191 | Z41: 19.816191 | AA41: 19.816191 | AB41: 19.816191 | AC41: 19.816191
B42: Milled peat | C42: MJ/kg | D42: Milled peat last used in 2023; subsequent years will use 2023 values | E42: 7.787448 | F42: 7.787448 | G42: 7.787448 | H42: 7.968171 | I42: 8.2129669 | J42: 8.5957991 | K42: 8.7883199 | L42: 8.0362271 | M42: 7.6784595 | N42: 7.9360406 | O42: 8.0400635 | P42: 7.7455353 | Q42: 8.0317627 | R42: 8.5271534 | S42: 8.5601457 | T42: 8.3123902 | U42: 8.0992843 | V42: 8.3195831 | W42: 8.4790378 | X42: 8.0425809 | Y42: 8.1929192 | Z42: 6.3812091 | AA42: 5.4267822 | AB42: 5.4267822 | AC42: 5.4267822
B43: Sod peat | C43: MJ/kg | E43: 13.104684 | F43: 13.104684 | G43: 13.104684 | H43: 13.104684 | I43: 13.104684 | J43: 13.104684 | K43: 13.104684 | L43: 13.104684 | M43: 13.104684 | N43: 13.104684 | O43: 13.104684 | P43: 13.104684 | Q43: 13.104684 | R43: 13.104684 | S43: 13.104684 | T43: 13.104684 | U43: 13.104684 | V43: 13.104684 | W43: 13.104684 | X43: 13.104684 | Y43: 13.104684 | Z43: 13.104684 | AA43: 13.104684 | AB43: 13.104684 | AC43: 13.104684
B44: Peat briquettes | C44: MJ/kg | E44: 18.547524 | F44: 18.547524 | G44: 18.547524 | H44: 18.547524 | I44: 18.547524 | J44: 18.547524 | K44: 18.547524 | L44: 18.547524 | M44: 18.547524 | N44: 18.547524 | O44: 18.547524 | P44: 18.547524 | Q44: 18.547524 | R44: 18.547524 | S44: 18.547524 | T44: 18.547524 | U44: 18.547524 | V44: 18.547524 | W44: 18.547524 | X44: 18.547524 | Y44: 18.547524 | Z44: 18.547524 | AA44: 18.547524 | AB44: 18.547524 | AC44: 18.547524
B46: Biomass
B47: Wood pellets & briquettes | C47: MJ/kg | E47: 17.28 | F47: 17.28 | G47: 17.28 | H47: 17.28 | I47: 17.28 | J47: 17.28 | K47: 17.28 | L47: 17.28 | M47: 17.28 | N47: 17.28 | O47: 17.28 | P47: 17.28 | Q47: 17.28 | R47: 17.28 | S47: 17.28 | T47: 17.28 | U47: 17.28 | V47: 17.28 | W47: 17.28 | X47: 17.28 | Y47: 17.28 | Z47: 17.28 | AA47: 17.28 | AB47: 17.28 | AC47: 17.28
B48: Wood logs & chips | C48: MJ/kg | D48: Assumes 25% moisture content | E48: 13.11 | F48: 13.11 | G48: 13.11 | H48: 13.11 | I48: 13.11 | J48: 13.11 | K48: 13.11 | L48: 13.11 | M48: 13.11 | N48: 13.11 | O48: 13.11 | P48: 13.11 | Q48: 13.11 | R48: 13.11 | S48: 13.11 | T48: 13.11 | U48: 13.11 | V48: 13.11 | W48: 13.11 | X48: 13.11 | Y48: 13.11 | Z48: 13.11 | AA48: 13.11 | AB48: 13.11 | AC48: 13.11
...

Sheet Emission factors timeseries
B2: Emission factors timeseries
B3: Unless otherwise stated, all values are based on net calorific value (NCV).
B5: Comments
B6: - The emission factors below show the quantity of CO2 produced per unit of energy for each fuel.
B7: - Combustion of fuels produces small quantities of greenhouse gases other than CO2 (i.e. CH4 and N2O), the quantities of which depend on the combustion conditions as well as fuel properties.
B8: - Emission factors for CH4 and N2O are not included in this spreadsheet.
B9: - SEAI recommends consulting the EPA's National Inventory Submissions for details on sector specific factors for CH4 and N2O.
B10: - With the exception of electricity, the emission factors include only direct CO2 emissions from combustion of fuels.
B11: - The net emission of CO2 from the combustion of biogenic carbon in sustainable biomass fuel (incl. solid biomass, biofuel, bioliquid and biogas) is considered to be zero, as it is assumed that the biomass itself absorbs an equal amount of CO2 during growth as is emitted during combustion.
B12: - Where biomass fuel is not sustainably produced, CO2 emissions from combustion should be counted. This is consistent with guidelines for greenhouse gas reporting, such as the IPCC 2006 Guideline for National Greeenhouse Gas Inventories & 2019 refinement and EU Emission Trading System.
B13: - Biodiesel methyl ester (ME) CO2 factor is based on a fossil carbon content of 5.4%, as per EPA's National Inventory Submissions 2025.
B15: Electricity
... B19: - SEAI does not currently publish 'well to tank' factors for electricity, which account for scope 3 emissions from extraction, refining and transportation of fuels used for electricity generation.
B21: Liquid | C21: Unit | D21: Note | E21: 2001 | F21: =E21+1 -> 2002 | G21: =F21+1 -> 2003 | H21: =G21+1 -> 2004 | I21: =H21+1 -> 2005 | J21: =I21+1 -> 2006 | K21: =J21+1 -> 2007 | L21: =K21+1 -> 2008 | M21: =L21+1 -> 2009 | ... AC21: =AB21+1 -> 2025
B22: Petroleum
B23: Crude oil | C23: gCO2/kWh | E23: 264 | F23: 264 | G23: 264 | H23: 264 | I23: 264 | J23: 264 | K23: 264 | L23: 264 | M23: 264 | N23: 264 | O23: 264 | P23: 264 | Q23: 264 | R23: 264 | S23: 264 | T23: 264 | U23: 264 | V23: 264 | W23: 264 | X23: 264 | Y23: 264 | Z23: 264 | AA23: 264 | AB23: 264 | AC23: 264
B24: Gasoline / petrol (100% petroleum) | C24: gCO2/kWh | E24: 251.856 | F24: 251.856 | G24: 251.856 | H24: 251.856 | I24: 251.856 | J24: 251.856 | K24: 251.856 | L24: 251.856 | M24: 251.856 | N24: 251.856 | O24: 251.856 | P24: 251.856 | Q24: 251.856 | R24: 251.856 | S24: 251.856 | T24: 251.856 | U24: 251.856 | V24: 251.856 | W24: 251.856 | X24: 251.856 | Y24: 251.856 | Z24: 251.856 | AA24: 251.856 | AB24: 251.856 | AC24: 251.856
B25: Kerosene | C25: gCO2/kWh | E25: 257.004 | F25: 257.004 | G25: 257.004 | H25: 257.004 | I25: 257.004 | J25: 257.004 | K25: 257.004 | L25: 257.004 | M25: 257.004 | N25: 257.004 | O25: 257.004 | P25: 257.004 | Q25: 257.004 | R25: 257.004 | S25: 257.004 | T25: 257.004 | U25: 257.004 | V25: 257.004 | W25: 257.004 | X25: 257.004 | Y25: 257.004 | Z25: 257.004 | AA25: 257.004 | AB25: 257.004 | AC25: 257.004
B26: Jet Kerosene | C26: gCO2/kWh | E26: 257.004 | F26: 257.004 | G26: 257.004 | H26: 257.004 | I26: 257.004 | J26: 257.004 | K26: 257.004 | L26: 257.004 | M26: 257.004 | N26: 257.004 | O26: 257.004 | P26: 257.004 | Q26: 257.004 | R26: 257.004 | S26: 257.004 | T26: 257.004 | U26: 257.004 | V26: 257.004 | W26: 257.004 | X26: 257.004 | Y26: 257.004 | Z26: 257.004 | AA26: 257.004 | AB26: 257.004 | AC26: 257.004
B27: Diesel / gasoil (100% petroleum) | C27: gCO2/kWh | E27: 263.868 | F27: 263.868 | G27: 263.868 | H27: 263.868 | I27: 263.868 | J27: 263.868 | K27: 263.868 | L27: 263.868 | M27: 263.868 | N27: 263.868 | O27: 263.868 | P27: 263.868 | Q27: 263.868 | R27: 263.868 | S27: 263.868 | T27: 263.868 | U27: 263.868 | V27: 263.868 | W27: 263.868 | X27: 263.868 | Y27: 263.868 | Z27: 263.868 | AA27: 263.868 | AB27: 263.868 | AC27: 263.868
B28: Residual fuel oil / fuel oil | C28: gCO2/kWh | E28: 273.636 | F28: 273.636 | G28: 273.636 | H28: 273.636 | I28: 273.636 | J28: 273.636 | K28: 273.636 | L28: 273.636 | M28: 273.636 | N28: 273.636 | O28: 273.636 | P28: 273.636 | Q28: 273.636 | R28: 273.636 | S28: 273.636 | T28: 273.636 | U28: 273.636 | V28: 273.636 | W28: 273.636 | X28: 273.636 | Y28: 273.636 | Z28: 273.636 | AA28: 273.636 | AB28: 273.636 | AC28: 273.636
B29: LPG | C29: gCO2/kWh | E29: 229.284 | F29: 229.284 | G29: 229.284 | H29: 229.284 | I29: 229.284 | J29: 229.284 | K29: 229.284 | L29: 229.284 | M29: 229.284 | N29: 229.284 | O29: 229.284 | P29: 229.284 | Q29: 229.284 | R29: 229.284 | S29: 229.284 | T29: 229.284 | U29: 229.284 | V29: 229.284 | W29: 229.284 | X29: 229.284 | Y29: 229.284 | Z29: 229.284 | AA29: 229.284 | AB29: 229.284 | AC29: 229.284
B31: Biofuel / bioliquid
B32: Bioethanol | C32: gCO2/kWh | E32: - | F32: - | G32: - | H32: - | I32: - | J32: - | K32: - | L32: - | M32: - | N32: - | O32: - | P32: - | Q32: - | R32: - | S32: - | T32: - | U32: - | V32: - | W32: - | X32: - | Y32: - | Z32: - | AA32: - | AB32: - | AC32: -
B33: Biodiesel ME | C33: gCO2/kWh | D33: Methyl ester; based on 5.4% fossil carbon | E33: 14.629785 | F33: 14.629785 | G33: 14.629785 | H33: 14.629785 | I33: 14.629785 | J33: 14.629785 | K33: 14.629785 | L33: 14.629785 | M33: 14.629785 | N33: 14.629785 | O33: 14.629785 | P33: 14.629785 | Q33: 14.629785 | R33: 14.629785 | S33: 14.629785 | T33: 14.629785 | U33: 14.629785 | V33: 14.629785 | W33: 14.629785 | X33: 14.629785 | Y33: 14.629785 | Z33: 14.629785 | AA33: 14.629785 | AB33: 14.629785 | AC33: 14.629785
B34: Biodiesel HVO | C34: gCO2/kWh | D34: Hydrotreated vegetable oil | E34: - | F34: - | G34: - | H34: - | I34: - | J34: - | K34: - | L34: - | M34: - | N34: - | O34: - | P34: - | Q34: - | R34: - | S34: - | T34: - | U34: - | V34: - | W34: - | X34: - | Y34: - | Z34: - | AA34: - | AB34: - | AC34: -
B35: Biodiesel CHVO | C35: gCO2/kWh | D35: Co-processed hydrotreated vegetable oil | E35: - | F35: - | G35: - | H35: - | I35: - | J35: - | K35: - | L35: - | M35: - | N35: - | O35: - | P35: - | Q35: - | R35: - | S35: - | T35: - | U35: - | V35: - | W35: - | X35: - | Y35: - | Z35: - | AA35: - | AB35: - | AC35: -
B36: Biopropane | C36: gCO2/kWh | E36: - | F36: - | G36: - | H36: - | I36: - | J36: - | K36: - | L36: - | M36: - | N36: - | O36: - | P36: - | Q36: - | R36: - | S36: - | T36: - | U36: - | V36: - | W36: - | X36: - | Y36: - | Z36: - | AA36: - | AB36: - | AC36: -
B37: Biojet HVO | C37: gCO2/kWh | D37: Hydrotreated vegetable oil | E37: - | F37: - | G37: - | H37: - | I37: - | J37: - | K37: - | L37: - | M37: - | N37: - | O37: - | P37: - | Q37: - | R37: - | S37: - | T37: - | U37: - | V37: - | W37: - | X37: - | Y37: - | Z37: - | AA37: - | AB37: - | AC37: -
B39: Blended petroleum & biofuel
B40: Road diesel (avg. biofuel content) | C40: gCO2/kWh | E40: {=_xlfn._xlws.FILTER(road_diesel_blend[Blend_gCO2_kWh],road_diesel_blend[Year]=E$21)} -> 263.88 | F40: {=_xlfn._xlws.FILTER(road_diesel_blend[Blend_gCO2_kWh],road_diesel_blend[Year]=F$21)} -> 263.88 | G40: {=_xlfn._xlws.FILTER(road_diesel_blend[Blend_gCO2_kWh],road_diesel_blend[Year]=G$21)} -> 263.88 | H40: {=_xlfn._xlws.FILTER(road_diesel_blend[Blend_gCO2_kWh],road_diesel_blend[Year]=H$21)} -> 263.88 | I40: {=_xlfn._xlws.FILTER(road_diesel_blend[Blend_gCO2_kWh],road_diesel_blend[Year]=I$21)} -> 263.75894 | J40: {=_xlfn._xlws.FILTER(road_diesel_blend[Blend_gCO2_kWh],road_diesel_blend[Year]=J$21)} -> 263.66757 | K40: {=_xlfn._xlws.FILTER(road_diesel_blend[Blend_gCO2_kWh],road_diesel_blend[Year]=K$21)} -> 262.18636 | L40: {=_xlfn._xlws.FILTER(road_diesel_blend[Blend_gCO2_kWh],road_diesel_blend[Year]=L$21)} -> 260.16434 | ... AC40: {=_xlfn._xlws.FILTER(road_diesel_blend[Blend_gCO2_kWh],road_diesel_blend[Year]=AC$21)} -> 239.04139
B41: Road petrol (avg. biofuel content) | C41: gCO2/kWh | E41: {=_xlfn._xlws.FILTER(road_petrol_blend[Blend_gCO2_kWh],road_petrol_blend[Year]=E$21)} -> 251.856 | F41: {=_xlfn._xlws.FILTER(road_petrol_blend[Blend_gCO2_kWh],road_petrol_blend[Year]=F$21)} -> 251.856 | G41: {=_xlfn._xlws.FILTER(road_petrol_blend[Blend_gCO2_kWh],road_petrol_blend[Year]=G$21)} -> 251.856 | H41: {=_xlfn._xlws.FILTER(road_petrol_blend[Blend_gCO2_kWh],road_petrol_blend[Year]=H$21)} -> 251.856 | I41: {=_xlfn._xlws.FILTER(road_petrol_blend[Blend_gCO2_kWh],road_petrol_blend[Year]=I$21)} -> 251.85485 | J41: {=_xlfn._xlws.FILTER(road_petrol_blend[Blend_gCO2_kWh],road_petrol_blend[Year]=J$21)} -> 251.76812 | K41: {=_xlfn._xlws.FILTER(road_petrol_blend[Blend_gCO2_kWh],road_petrol_blend[Year]=K$21)} -> 251.38757 | L41: {=_xlfn._xlws.FILTER(road_petrol_blend[Blend_gCO2_kWh],road_petrol_blend[Year]=L$21)} -> 249.37387 | ... AC41: {=_xlfn._xlws.FILTER(road_petrol_blend[Blend_gCO2_kWh],road_petrol_blend[Year]=AC$21)} -> 235.55659
B44: Solid | C44: Unit | D44: Note | E44: 2001 | F44: =E44+1 -> 2002 | G44: =F44+1 -> 2003 | H44: =G44+1 -> 2004 | I44: =H44+1 -> 2005 | J44: =I44+1 -> 2006 | K44: =J44+1 -> 2007 | L44: =K44+1 -> 2008 | M44: =L44+1 -> 2009 | ... AC44: =AB44+1 -> 2025
B45: Fossil fuel
B46: Petroleum coke | C46: gCO2/kWh | E46: 337.13343 | F46: 337.13343 | G46: 337.13343 | H46: 337.13343 | I46: 342.44305 | J46: 336.36136 | K46: 335.54381 | L46: 334.55509 | M46: 336.76383 | N46: 336.953 | O46: 335.67506 | P46: 334.2113 | Q46: 334.59163 | R46: 334.25247 | S46: 340.33698 | T46: 340.00449 | U46: 339.8752 | V46: 339.66195 | W46: 336.74968 | X46: 337.45775 | Y46: 338.67685 | Z46: 344.9731 | AA46: 338.56709 | AB46: 336.1168 | AC46: 336.1168
B47: Bituminous coal | C47: gCO2/kWh | E47: 340.56 | F47: 340.56 | G47: 340.56 | H47: 340.56 | I47: 340.56 | J47: 340.56 | K47: 340.56 | L47: 340.56 | M47: 340.56 | N47: 340.56 | O47: 340.56 | P47: 340.56 | Q47: 340.56 | R47: 340.56 | S47: 340.56 | T47: 340.56 | U47: 340.56 | V47: 340.56 | W47: 340.56 | X47: 340.56 | Y47: 340.56 | Z47: 340.56 | AA47: 340.56 | AB47: 340.56 | AC47: 340.56
B48: Anthracite | C48: gCO2/kWh | E48: 353.8788 | F48: 353.8788 | G48: 353.8788 | H48: 353.8788 | I48: 353.8788 | J48: 353.8788 | K48: 353.8788 | L48: 353.8788 | M48: 353.8788 | N48: 353.8788 | O48: 353.8788 | P48: 353.8788 | Q48: 353.8788 | R48: 353.8788 | S48: 353.8788 | T48: 353.8788 | U48: 353.8788 | V48: 353.8788 | W48: 353.8788 | X48: 353.8788 | Y48: 353.8788 | Z48: 353.8788 | AA48: 353.8788 | AB48: 353.8788 | AC48: 353.8788
B49: Lignite | C49: gCO2/kWh | E49: 363.594 | F49: 363.594 | G49: 363.594 | H49: 363.594 | I49: 363.594 | J49: 363.594 | K49: 363.594 | L49: 363.594 | M49: 363.594 | N49: 363.594 | O49: 363.594 | P49: 363.594 | Q49: 363.594 | R49: 363.594 | S49: 363.594 | T49: 363.594 | U49: 363.594 | V49: 363.594 | W49: 363.594 | X49: 363.594 | Y49: 363.594 | Z49: 363.594 | AA49: 363.594 | AB49: 363.594 | AC49: 363.594
B50: Milled peat | C50: gCO2/kWh | D50: Milled peat last used in 2023; subsequent years will use 2023 values | E50: 390.324 | F50: 390.324 | G50: 390.324 | H50: 438.9792 | I50: 419.24814 | J50: 411.95812 | K50: 406.64096 | L50: 415.99963 | M50: 420.01902 | N50: 412.95349 | O50: 413.78324 | P50: 417.91991 | Q50: 424.76901 | R50: 422.18375 | S50: 414.13822 | T50: 419.90249 | U50: 420.92135 | V50: 406.40417 | W50: 407.87804 | X50: 418.0622 | Y50: 430.50413 | Z50: 475.61449 | AA50: 491.70365 | AB50: 491.70365 | AC50: 491.70365
B51: Sod peat | C51: gCO2/kWh | E51: 374.4 | F51: 374.4 | G51: 374.4 | H51: 374.4 | I51: 374.4 | J51: 374.4 | K51: 374.4 | L51: 374.4 | M51: 374.4 | N51: 374.4 | O51: 374.4 | P51: 374.4 | Q51: 374.4 | R51: 374.4 | S51: 374.4 | T51: 374.4 | U51: 374.4 | V51: 374.4 | W51: 374.4 | X51: 374.4 | Y51: 374.4 | Z51: 374.4 | AA51: 374.4 | AB51: 374.4 | AC51: 374.4
...

Sheet Density timeseries
B2: Density
B5: Liquid | C5: Units | D5: Note | E5: 2001 | F5: =E5+1 -> 2002 | G5: =F5+1 -> 2003 | H5: =G5+1 -> 2004 | I5: =H5+1 -> 2005 | J5: =I5+1 -> 2006 | K5: =J5+1 -> 2007 | L5: =K5+1 -> 2008 | M5: =L5+1 -> 2009 | ... AC5: =AB5+1 -> 2025
B6: Petroleum
B7: Crude oil | C7: kg/m^3 | E7: =10^6/1067 -> 937.20712 | F7: =10^6/1067 -> 937.20712 | G7: =10^6/1067 -> 937.20712 | H7: =10^6/1067 -> 937.20712 | I7: =10^6/1067 -> 937.20712 | J7: =10^6/1067 -> 937.20712 | K7: =10^6/1067 -> 937.20712 | L7: =10^6/1067 -> 937.20712 | ... AC7: =10^6/1067 -> 937.20712
B8: Gasoline / petrol (100% petroleum) | C8: kg/m^3 | E8: 755 | F8: 755 | G8: 755 | H8: 755 | I8: 740.74074 | J8: 740.74074 | K8: 740.74074 | L8: 740.74074 | M8: 740.74074 | N8: 740.74074 | O8: 740.74074 | P8: 740.74074 | Q8: 740.74074 | R8: 740.74074 | S8: 740.74074 | T8: 740.74074 | U8: 740.74074 | V8: 740.74074 | W8: 740.74074 | X8: 740.74074 | Y8: 740.74074 | Z8: 740.74074 | AA8: 740.74074 | AB8: 740.74074 | AC8: 740.74074
B9: Kerosene | C9: kg/m^3 | E9: 800 | F9: 800 | G9: 800 | H9: 800 | I9: 800 | J9: 800 | K9: 800 | L9: 800 | M9: 800 | N9: 800 | O9: 800 | P9: 800 | Q9: 800 | R9: 800 | S9: 800 | T9: 800 | U9: 800 | V9: 800 | W9: 800 | X9: 800 | Y9: 800 | Z9: 800 | AA9: 800 | AB9: 800 | AC9: 800
B10: Jet Kerosene | C10: kg/m^3 | E10: 800 | F10: 800 | G10: 800 | H10: 800 | I10: 800 | J10: 800 | K10: 800 | L10: 800 | M10: 800 | N10: 800 | O10: 800 | P10: 800 | Q10: 800 | R10: 800 | S10: 800 | T10: 800 | U10: 800 | V10: 800 | W10: 800 | X10: 800 | Y10: 800 | Z10: 800 | AA10: 800 | AB10: 800 | AC10: 800
B11: Diesel / gasoil (100% petroleum) | C11: kg/m^3 | E11: 845 | F11: 845 | G11: 845 | H11: 845 | I11: 845 | J11: 845 | K11: 845 | L11: 845 | M11: 845 | N11: 845 | O11: 845 | P11: 845 | Q11: 845 | R11: 845 | S11: 845 | T11: 845 | U11: 845 | V11: 845 | W11: 845 | X11: 845 | Y11: 845 | Z11: 845 | AA11: 845 | AB11: 845 | AC11: 845
B12: Residual fuel oil / fuel oil | C12: kg/m^3 | E12: 941.61959 | F12: 941.61959 | G12: 941.61959 | H12: 941.61959 | I12: 941.61959 | J12: 941.61959 | K12: 941.61959 | L12: 941.61959 | M12: 941.61959 | N12: 941.61959 | O12: 941.61959 | P12: 941.61959 | Q12: 941.61959 | R12: 941.61959 | S12: 941.61959 | T12: 941.61959 | U12: 941.61959 | V12: 941.61959 | W12: 941.61959 | X12: 941.61959 | Y12: 941.61959 | Z12: 941.61959 | AA12: 941.61959 | AB12: 941.61959 | AC12: 941.61959
B13: LPG | C13: kg/m^3 | D13: Assumes a mixture of 70% propane & 30% butane by mass | E13: 522.19321 | F13: 522.19321 | G13: 522.19321 | H13: 522.19321 | I13: 522.19321 | J13: 522.19321 | K13: 522.19321 | L13: 522.19321 | M13: 522.19321 | N13: 522.19321 | O13: 522.19321 | P13: 522.19321 | Q13: 522.19321 | R13: 522.19321 | S13: 522.19321 | T13: 522.19321 | U13: 522.19321 | V13: 522.19321 | W13: 522.19321 | X13: 522.19321 | Y13: 522.19321 | Z13: 522.19321 | AA13: 522.19321 | AB13: 522.19321 | AC13: 522.19321
B15: Biofuel / bioliquid
B16: Bioethanol | C16: kg/m^3 | E16: 800 | F16: 800 | G16: 800 | H16: 800 | I16: 800 | J16: 800 | K16: 800 | L16: 800 | M16: 800 | N16: 800 | O16: 800 | P16: 800 | Q16: 800 | R16: 800 | S16: 800 | T16: 800 | U16: 800 | V16: 800 | W16: 800 | X16: 800 | Y16: 800 | Z16: 800 | AA16: 800 | AB16: 800 | AC16: 800
B17: Biodiesel ME | C17: kg/m^3 | D17: Methyl ester | E17: 880 | F17: 880 | G17: 880 | H17: 880 | I17: 880 | J17: 880 | K17: 880 | L17: 880 | M17: 880 | N17: 880 | O17: 880 | P17: 880 | Q17: 880 | R17: 880 | S17: 880 | T17: 880 | U17: 880 | V17: 880 | W17: 880 | X17: 880 | Y17: 880 | Z17: 880 | AA17: 880 | AB17: 880 | AC17: 880
B18: Biodiesel HVO | C18: kg/m^3 | D18: Hydrotreated vegetable oil | R18: 772.72727 | S18: 772.72727 | T18: 772.72727 | U18: 772.72727 | V18: 772.72727 | W18: 772.72727 | X18: 772.72727 | Y18: 772.72727 | Z18: 772.72727 | AA18: 772.72727 | AB18: 772.72727 | AC18: 772.72727
B19: Biodiesel CHVO | C19: kg/m^3 | D19: Co-processed hydrotreated vegetable oil | R19: 837.2093 | S19: 837.2093 | T19: 837.2093 | U19: 837.2093 | V19: 837.2093 | W19: 837.2093 | X19: 837.2093 | Y19: 837.2093 | Z19: 837.2093 | AA19: 837.2093 | AB19: 837.2093 | AC19: 837.2093
B20: Biopropane | C20: kg/m^3 | R20: 521.73913 | S20: 521.73913 | T20: 521.73913 | U20: 521.73913 | V20: 521.73913 | W20: 521.73913 | X20: 521.73913 | Y20: 521.73913 | Z20: 521.73913 | AA20: 521.73913 | AB20: 521.73913 | AC20: 521.73913
B21: Biojet HVO | C21: kg/m^3 | D21: Hydrotreated vegetable oil | R21: 772.72727 | S21: 772.72727 | T21: 772.72727 | U21: 772.72727 | V21: 772.72727 | W21: 772.72727 | X21: 772.72727 | Y21: 772.72727 | Z21: 772.72727 | AA21: 772.72727 | AB21: 772.72727 | AC21: 772.72727
B23: Blended petroleum & biofuel
B24: Road diesel (avg. biofuel content) | C24: kg/m^3 | E24: {=_xlfn._xlws.FILTER(road_diesel_blend[Blend_kg_l],road_diesel_blend[Year]=E$5)*1000} -> 845 | F24: {=_xlfn._xlws.FILTER(road_diesel_blend[Blend_kg_l],road_diesel_blend[Year]=F$5)*1000} -> 845 | G24: {=_xlfn._xlws.FILTER(road_diesel_blend[Blend_kg_l],road_diesel_blend[Year]=G$5)*1000} -> 845 | H24: {=_xlfn._xlws.FILTER(road_diesel_blend[Blend_kg_l],road_diesel_blend[Year]=H$5)*1000} -> 845 | I24: {=_xlfn._xlws.FILTER(road_diesel_blend[Blend_kg_l],road_diesel_blend[Year]=I$5)*1000} -> 845.02449 | J24: {=_xlfn._xlws.FILTER(road_diesel_blend[Blend_kg_l],road_diesel_blend[Year]=J$5)*1000} -> 845.05392 | K24: {=_xlfn._xlws.FILTER(road_diesel_blend[Blend_kg_l],road_diesel_blend[Year]=K$5)*1000} -> 845.2879 | L24: {=_xlfn._xlws.FILTER(road_diesel_blend[Blend_kg_l],road_diesel_blend[Year]=L$5)*1000} -> 845.62175 | ... AC24: {=_xlfn._xlws.FILTER(road_diesel_blend[Blend_kg_l],road_diesel_blend[Year]=AC$5)*1000} -> 845.15839
B25: Road petrol (avg. biofuel content) | C25: kg/m^3 | E25: {=_xlfn._xlws.FILTER(road_petrol_blend[Blend_kg_l],road_petrol_blend[Year]=E$5)*1000} -> 755 | F25: {=_xlfn._xlws.FILTER(road_petrol_blend[Blend_kg_l],road_petrol_blend[Year]=F$5)*1000} -> 755 | G25: {=_xlfn._xlws.FILTER(road_petrol_blend[Blend_kg_l],road_petrol_blend[Year]=G$5)*1000} -> 755 | H25: {=_xlfn._xlws.FILTER(road_petrol_blend[Blend_kg_l],road_petrol_blend[Year]=H$5)*1000} -> 755 | I25: {=_xlfn._xlws.FILTER(road_petrol_blend[Blend_kg_l],road_petrol_blend[Year]=I$5)*1000} -> 740.74116 | J25: {=_xlfn._xlws.FILTER(road_petrol_blend[Blend_kg_l],road_petrol_blend[Year]=J$5)*1000} -> 740.77295 | K25: {=_xlfn._xlws.FILTER(road_petrol_blend[Blend_kg_l],road_petrol_blend[Year]=K$5)*1000} -> 740.91228 | L25: {=_xlfn._xlws.FILTER(road_petrol_blend[Blend_kg_l],road_petrol_blend[Year]=L$5)*1000} -> 741.64566 | ... AC25: {=_xlfn._xlws.FILTER(road_petrol_blend[Blend_kg_l],road_petrol_blend[Year]=AC$5)*1000} -> 746.5075

Sheet Primary energy timeseries
B2: Primary energy factors
B3: Unless otherwise stated, all values are based on net calorific value (NCV).
B5: Comments
B6: - Energy consumption can be measured as final energy or primary energy.
B7: - Primary energy accounts for the energy that is consumed and/or lost in transformation, transmission and distribution processes.
B8: - Primary energy can be calculated by applying conversion factors, which vary by fuel or energy type, to final energy values.
B9: - The table below shows default primary energy factors for liquid, solid and gaseous fuels.
B10: - The table also shows the annual primary energy factor for Ireland's electricity based on the generation mix that year.
B13: Liquid | C13: Unit | D13: Note | E13: Default value
B14: Petroleum
B15: Crude oil | C15: - | E15: -
B16: Gasoline / petrol (100% petroleum) | C16: - | E16: 1.1
B17: Kerosene | C17: - | E17: 1.1
B18: Jet Kerosene | C18: - | E18: 1.1
B19: Diesel / gasoil (100% petroleum) | C19: - | E19: 1.1
B20: Residual fuel oil / fuel oil | C20: - | E20: 1.1
B21: LPG | C21: - | E21: 1.1
B23: Biofuel / bioliquid
B24: Bioethanol | C24: - | E24: 1.1
B25: Biodiesel ME | C25: - | E25: 1.1
B26: Biodiesel HVO | C26: - | E26: 1.1
B27: Biodiesel CHVO | C27: - | E27: 1.1
B28: Biopropane | C28: - | E28: 1.1
B29: Biojet HVO | C29: - | E29: 1.1
B31: Blended petroleum & biofuel
B32: Road diesel (avg. biofuel content) | C32: - | E32: 1.1
B33: Road petrol (avg. biofuel content) | C33: - | E33: 1.1
B36: Solid | C36: Unit | D36: Note | E36: Default value
B37: Fossil fuel
B38: Petroleum coke | C38: - | E38: 1.1
B39: Bituminous coal | C39: - | E39: 1.1
B40: Anthracite | C40: - | E40: 1.1
B41: Lignite | C41: - | E41: 1.1
B42: Milled peat | C42: - | E42: 1.1
B43: Sod peat | C43: - | E43: 1.1
B44: Peat briquettes | C44: - | E44: 1.1
B46: Biomass
B47: Wood pellets & briquettes | C47: gCO2/kWh | E47: 1.1
B48: Wood logs & chips | C48: gCO2/kWh | D48: Assumes 25% moisture content | E48: 1.1
B51: Gas | C51: Unit | D51: Note | E51: Default value
...

Sheet road_petrol_blend
A1: Year | B1: Blend_kg_l | C1: Blend_mj_kg | D1: Blend_gCO2_kWh
A2: 2001 | B2: 0.755 | C2: 44.58942 | D2: 251.856
A3: 2002 | B3: 0.755 | C3: 44.58942 | D3: 251.856
A4: 2003 | B4: 0.755 | C4: 44.58942 | D4: 251.856
A5: 2004 | B5: 0.755 | C5: 44.58942 | D5: 251.856
A6: 2005 | B6: 0.74074116 | C6: 44.589281 | D6: 251.85485
A7: 2006 | B7: 0.74077295 | C7: 44.578802 | D7: 251.76812
A8: 2007 | B8: 0.74091228 | C8: 44.532881 | D8: 251.38757
A9: 2008 | B9: 0.74164566 | C9: 44.291451 | D9: 249.37387
A10: 2009 | B10: 0.74200105 | C10: 44.174627 | D10: 248.39156
A11: 2010 | B11: 0.74256832 | C11: 43.988387 | D11: 246.8148
A12: 2011 | B12: 0.74260016 | C12: 43.977942 | D12: 246.72598
A13: 2012 | B13: 0.74274662 | C13: 43.929907 | D13: 246.31693
... A26: 2025 | B26: 0.7465075 | C26: 42.702923 | D26: 235.55659

Sheet road_diesel_blend
A1: Year | B1: Blend_kg_l | C1: Blend_mj_kg | D1: Blend_gCO2_kWh
A2: 2001 | B2: 0.845 | C2: 43.308259 | D2: 263.88
A3: 2002 | B3: 0.845 | C3: 43.308259 | D3: 263.88
A4: 2003 | B4: 0.845 | C4: 43.308259 | D4: 263.88
A5: 2004 | B5: 0.845 | C5: 43.308259 | D5: 263.88
A6: 2005 | B6: 0.84502449 | C6: 43.304914 | D6: 263.75894
A7: 2006 | B7: 0.84505392 | C7: 43.30251 | D7: 263.66757
A8: 2007 | B8: 0.8452879 | C8: 43.260909 | D8: 262.18636
A9: 2008 | B9: 0.84562175 | C9: 43.204412 | D9: 260.16434
A10: 2009 | B10: 0.84593713 | C10: 43.144352 | D10: 258.02364
A11: 2010 | B11: 0.84615207 | C11: 43.109486 | D11: 256.7665
A12: 2011 | B12: 0.84621401 | C12: 43.090955 | D12: 256.11682
A13: 2012 | B13: 0.84600544 | C13: 43.128197 | D13: 257.45295
... A26: 2025 | B26: 0.84515839 | C26: 42.951901 | D26: 239.04139

Sheet GHG_elec
A1: Year | B1: Electricity_AFC_gCO2_kWh | C1: Gross_Electricity_Supply_gCO2_kWh
A2: 2001 | B2: 808.93327 | C2: 694.37223
A3: 2002 | B3: 746.56162 | C3: 640.87874
A4: 2003 | B4: 679.14206 | C4: 586.01414
A5: 2004 | B5: 643.51436 | C5: 557.6265
A6: 2005 | B6: 638.55713 | C6: 556.36212
A7: 2006 | B7: 598.73583 | C7: 519.45678
A8: 2007 | B8: 562.68219 | C8: 490.1706
A9: 2008 | B9: 549.05223 | C9: 478.75907
A10: 2009 | B10: 525.06798 | C10: 457.65803
A11: 2010 | B11: 530.31586 | C11: 468.55854
A12: 2011 | B12: 489.35327 | C12: 435.52243
A13: 2012 | B13: 532.28515 | C13: 469.76116
... A26: 2025 | B26: 197.80338 | C26: 178.32767
