Workbook

Sheet Allgemeine_Hinweise
A1: Diese Seite enthält Informationen zur Version der bereitgestellten Liste mit Emissionsfaktoren, Allgemeine Hinweise, Bilanzgrenzen, Haftungsausschluss, Rückmeldungen und Verbesserungsvorschläge einen Ausblick sowie die am Redaktionsprozess beteiligten Facheinheiten des Umweltbundesamtes.
A8: Liste mit Emissionsfaktoren für die Treibhausgasbilanzierung von Organisationen
A9: List of emission factors for the greenhouse gas accounting of organisations
A11: Version
A12: V 2.1
A13: Fertigstellung: März 2026
A15: Allgemeine Hinweise
A16: Die in dieser Liste enthaltenen Emissionsfaktoren wurden durch das Umweltbundesamt auf Basis von eigenen und extern vergebenen Forschungsprojekten sowie weiteren Quellen zusammengetragen. Für jeden aufgeführten Emissionsfaktor ist die jeweilige Datenquelle angegeben. Eine Differenzierung nach Treibhausgasen (CO₂, CH₄, N₂O) erfolgt dort, wo die Daten verfügbar sind und eine Aufteilung notwendig ist. Eine Differenzierung nach weiteren Treibhausgasen oder Nicht-CO₂ Effekten wird nur in Ausnahmefällen vorgenommen. Die zugrunde gelegten Global Warming Potentials (GWPs) für viele Emissionsfaktoren entsprechen meist dem 5. Sachstandsbericht (AR5) des Intergovernmental Panel on Climate Change (IPCC) für einen Zeitraum von 100 Jahren. Hintergrund dafür sind internationale Berichtsstandards auf denen viele der angegebenen Werte beruhen. Die veröffentlichten Emissionsfaktoren stellen ausschließlich generische Referenzwerte dar. Liegen der nutzenden Organisation belastbare aktivitätsspezifische Emissionsfaktoren vor, sind diese den generischen Werten vorzuziehen. Die Emissionsfaktorenliste orientiert sich am Corporate Standard des Greenhouse Gas Protocols. In folgenden Punkten ist die Übereinstimmung aufgrund fehlender Daten nicht vollständig möglich: - Die zugrunde gelegten Emissionsfaktoren basieren in großen Teilen auf GWPs aus dem 5. Sachstandsreport des IPCC (siehe Grund obenstehend). - Der Emissionsfaktor Strommix Deutschland wird inklusive Übertragungsnetzverlusten angegeben. Diese werden sowohl im Emissionsfaktor für die Vorkette, als auch bei den direkten Emissionen der Stromerzeugung jeweils anteilig berücksichtigt. - Emissionsfaktoren für Fernwärme entsprechen Gesamtwerten und können von uns nicht differenziert nach Primärenergieträger-Input und direkten und Vorkettenemissionsfaktoren bereitgestellt werden (Ausnahmen sind der Emissionsfaktor für den fossilen Fernwärmemix sowie für Fernwärme aus fester Biomasse). - Die Emissionsfaktorenliste ist in Handlungsfelder strukturiert, die den Scopes 1, 2 und 3 zugeordnet sind. Im Scope 3 folgt sie nicht den 15 Kategorien des GHG Protocol Corporate Standard. Eine Aktualisierung der bereitgestellten Emissionsfaktorenliste ist jährlich im Dezember vorgesehen. Fehler jeglicher Art werden im Rahmen kurzfristigerer Aktualisierungen korrigiert. Die jeweils geltende Version und der Stand werden durch entsprechende Nummerierung mit dazugehörigem Datum angezeigt.
A18: Bilanzgrenzen
A19: Die Bilanzierungsgrenzen entsprechen den Vorgaben des Greenhouse Gas Protocols und werden in den Blättern differenziert in Scope 1-3 aufgeführt (siehe Scope-Angaben in den Blättern sowie in den IDs der Emissionsfaktoren > Blatt "Technische_Hinweise")
A21: Haftungsausschluss
A22: Das Umweltbundesamt übernimmt keinerlei Gewähr für die Aktualität, Korrektheit, Vollständigkeit oder Qualität der bereitgestellten Informationen. Haftungsansprüche gegen das Umweltbundesamt welche sich auf Schäden materieller oder ideeller Art beziehen, die durch die Nutzung oder Nichtnutzung der dargebotenen Informationen bzw. durch die Nutzung fehlerhafter und unvollständiger Informationen verursacht wurden, sind grundsätzlich ausgeschlossen, sofern seitens des Umweltbundesamtes kein nachweislich vorsätzliches oder grob fahrlässiges Verschulden vorliegt. Alle Angebote der bereitgestellten Emissionsfaktoren sind freibleibend und unverbindlich. Das Umweltbundesamt behält es sich ausdrücklich vor, Teile der Emissionsfaktorenliste oder das gesamte Angebot ohne gesonderte Ankündigung zu verändern, zu ergänzen, zu löschen oder die Veröffentlichung zeitweise oder endgültig einzustellen. | C22: Quelle: Greenhouse gas protocol (2011): corporate value chain (Scope 3) accounting and reporting standard, supplement to the GHG protocol corporate accounting and reporting standard. World Resources Institute [Geneva, Switzerland]; World Business Council for Sustainable Development, Washington, DC. https://ghgprotocol.org/sites/default/files/standards/Corporate-Value-Chain-Accounting-Reporing-Standard-EReader_041613_0.pdf
A24: Rückmeldungen und Verbesserungsvorschläge
A25: Wir freuen uns über Ihr Feedback, Ihre Vorschläge und Fragen, um diese Liste weiter zu verbessern. Ihre Rückmeldungen können Sie uns gerne per E-Mail unter folgender Adresse senden: ef-liste@uba.de
A27: Ausblick
A28: Im Rahmen einer Erprobungsphase vor der Veröffentlichung der Emissionsfaktorenliste wurden uns viele Wünsche und Bedarfe zurückgemeldet. Einige davon konnten kurzfristig umgesetzt werden, während andere einen deutlich größeren Umsetzungsaufwand bedeuten. Um einen Ausblick auf kommende Erweiterungen der Emissionsfaktorenliste zu geben, seien folgende Beispiele für zukünftige Entwicklungen an dieser Stelle genannt: - Bereitstellung von weiteren Emissionsfaktoren für eingekaufte Güter und Dienstleistungen - Bereitstellung einer detaillierten Dokumentation als .pdf Wir bemühen uns, eine Vielzahl an Emissionsfaktoren bereitzustellen. Bitte haben Sie dafür Verständnis, dass wir dabei keine bestimmten Branchenwünsche mit den jeweils spezifischen Bedarfen an Emissionsfaktoren berücksichtigen können.
A30: Redaktion
A31: Fachgebiet I 1.5: Nachhaltige Unternehmen und Verwaltungen, Sustainable Finance, Umweltkosten
A32: Service- und Beratungsstelle zur Unterstützung der Koordinierungsstelle Klimaneutrale Bundesverwaltung (KKB)
A33: Fachgebiet III 2.1: Übergreifende Angelegenheiten, Chemische Industrie, Feuerungsanlagen

Sheet Inhaltsverzeichnis
A1: Diese Seite enthält ein Inhaltsverzeichnis.
A8: Inhaltsverzeichnis
A9: Scope | B9: Blattname / Link | C9: Beschreibung der enthaltenen Faktoren | D9: Beispiel für Emissionsfaktoren im jeweiligen Blatt | E9: ID / Link
A10: Scope 1 | B10: 01_Stationäre_Verbrennung | C10: Biogene und fossile Brennstoffe ohne Vorketten | D10: Verbrennung von Erdgas [1kWh] ohne Vorkette (Brennwert-bezogen) | E10: 01_10_02_005_01
A11: Scope 1 | B11: 02_Mobile_Verbrennung | C11: Biogene und fossile Brennstoffe für den Einsatz in mobilen Geräten, nach Kraftstoffverbrauch sowie nach nach Strecke/Fahrzeug für Güterfahrzeuge und Personenfahrzeuge ohne Vorketten | D11: Verbrennung von einem Liter Benzin in einem Auto, direkte Emissionen, ohne Vorkette | E11: 02_10_01_001_02
A12: Scope 1 | B12: 03_Industrieprozesse | C12: Direkte Emissionen aus Industrieprozessen | D12: Produktion von Zementklinker | E12: 03_10_01_001_04
A13: Scope 1 | B13: 04_Kältemittel u.a. | C13: Global Warming Potentials für Kältemittel und andere Verbindungen | D13: GWP von 1kg HFKW-134a | E13: 04_10_01_006_XX
A14: Scope 2 und 3 | B14: 05_Strom | C14: Strombezug in Deutschland | D14: Strommix in Deutschland mit Vorkette | E14: 05_32_01_001_01
A15: Scope 2 und 3 | B15: 06_Wärme | C15: Fernwärmebezug differenziert nach hauptsächlich verwendeter Bezugsquelle | D15: fossiler Fernwärme-Mix, Gesamtemissionen | E15: 06_32_01_008_01
A16: Scope 3 | B16: 07_Stat._Verbr. V.&m.V. | C16: Biogene und fossile Brennstoffe: Vorketten sowie inklusive Vorketten | D16: Verbrennung von Erdgas [1kWh], Vorkette | E16: 07_31_02_005_01
A17: Scope 3 | B17: 08_Dienstreisen_Arbeitswege_m.V. | C17: Biogene und fossile Brennstoffe nach Kraftstoffverbrauch sowie nach nach Strecke/Fahrzeug für Personenfahrzeuge: Vorketten sowie inklusive Vorketten | D17: Dienstreise mit dem Zug im Fernverkehr für 1 Person pro km (pkm) | E17: 08_32_03_038_09
A18: Scope 3 | B18: 09_Gütertransport_m.V. | C18: Biogene und fossile Brennstoffe nach Kraftstoffverbrauch sowie nach Strecke/Fahrzeug für Gütertransport: Vorketten sowie inklusive Vorketten | D18: Verbrennung von einem Liter Benzin in einem Auto, Vorkette | E18: 09_31_01_001_02
A19: Scope 3 | B19: 10_Güter_Dienstleistungen m.V. | C19: Verpflegung, IT-Dienstleistungen und Arbeitsplatzausstattung mit Vorketten | D19: Bezug von einem Notebook | E19: 10_32_01_005_XX
A20: Scope 3 | B20: 11_Abwasser | C20: Abwasseraufbereitung | D20: Abwasseraufbereitung in kommunalen Kläranlagen | E20: 11_32_01_001_05
A21: Scope 3 | B21: 12_Ressourcen m.V. | C21: Kunststoffe, Mineralien, Metalle, Anbauprodukte sowie organische und anorganische Chemikalien mit Vorketten > siehe BAFA-Informationsblatt
A22: Weiteres | B22: Außerhalb der Scopes | C22: CO2-Teil der Verbrennung von biogenen Brennstoffen | D22: CO2-Anteil bei der Verbrennung von Biogas [pro m3] | E22: XX_00_01_002_05
A23: Weiteres | B23: Anwendungshilfe Kältemittel | C23: Durchschnittliche Verlustwerte für Kältemittel (HFKW, FKW und Blends) in Produktion, Betrieb, Entsorgung und Vor-Ort-Installation | D23: Verlustanteil pro Jahr bezogen auf die Gesamtfüllmenge in einem Multi-Split-Gerät | E23: C44
A24: Weiteres | B24: Umrechnungsfaktoren | C24: Umrechnungsfaktoren
A25: Weiteres | B25: Change-log | C25: Änderungshistorie
A26: Weiteres | B26: Quellenverzeichnis | C26: Quellenverzeichnis
A27: Weiteres | B27: Impressum | C27: Impressum

Sheet Technische_Hinweise
A1: Technische Hinweise
A2: Dieses Blatt enthält technische Hinweise für die Anwendung der Emissionsfaktoren aus der vorliegenden Emissionsfaktorenliste.
A3: Die Änderungshistorie wird künftig in einem separaten Blatt (change-log) zu finden sein.
B5: Zellmarkierung für momentan noch fehlende Werte
A7: Anwendungshinweis für die Berücksichtigung von Emissionen "außerhalb der Scopes"
A8: Die biogenen CO2-Emissionen bleiben bei den brennstoff-bezogenen Emissionsfaktoren von biogenen Brennstoffen in Scope 1 und Scope 3 bislang unberücksichtigt. Diese Differenzierung ist laut GHG-Protocol erforderlich. Dieser Emissionsposten kann "außerhalb der Scopes" unter Nutzung des gleichnamigen Blattes, bei Bedarf berücksichtigt werden.
A9: Beispiel: | B9: Bioethanol [Angabe pro Liter] - die enthaltenen Werte sind Beispielwerte für das Bezugsjahr 2023
B10: ID | C10: Blatt | D10: enthält | E10: Einheit | F10: kg CO2e | G10: kg CO2 | H10: kg CH4 | I10: kg N2O | J10: Anmerkung
A11: Bioethanol (mobile Verbrennung) | B11: 02_10_01_003_04 | C11: 02_Mobile_Verbrennung | D11: direkte Emissionen (ohne biogenes CO2) | E11: l | F11: 0.1066 | G11: 0.1005 | H11: 0.000154 | I11: 6.66e-06 | J11: Die aufgeführten CO2-Emissionen berücksichtigen nur den fossilen CO2 Anteil im Brennstoff (z.B. durch Additive).
A12: Bioethanol (mobile Verbrennung) | B12: 08_31_01_003_02 | C12: 08_Arbeitswege_Dienstreisen_m.V. | D12: Vorkette | E12: l | F12: 0.19360926 | G12: 0.10533209 | H12: 0.0009979425 | I12: 0.00022767839 | J12: ID 08_31_01_003_02 Bioethanol auf dem Blatt 08_Arbeitswege_Dienstreisen_m.V. [Angabe pro Liter]: die aufgeführten Emissionen berücksichtigen die Vorketten
A13: Bioethanol (mobile Verbrennung) | B13: 08_32_02_003_02 | C13: 08_Arbeitswege_Dienstreisen_m.V. | D13: Gesamt, ohne biogenes CO2 | E13: l | F13: 0.30020926 | G13: 0.20583209 | H13: 0.0011519425 | I13: 0.00023433839 | J13: Summe aus direkten Emissionen und Vorkette entspricht ID 08_32_02_003_02 ("Gesamtwert", ohne biogene CO2-Emissionen)
A14: Bioethanol (mobile Verbrennung) | B14: XX_00_02_003_02 | C14: Außerhalb der Scopes | D14: biogene CO2-Emissionen | E14: l | F14: 1.4075 | G14: 1.4075 | H14: - | I14: - | J14: CO2-Emissionen aus der Verbrennung von Biomasse, hier Bioethanol
A15: Bioethanol (mobile Verbrennung) | B15: In der EF-Liste nicht enthalten. | C15: In der EF-Liste nicht enthalten. | D15: Gesamt, mit biogenem CO2 | E15: l | F15: 1.7077093 | G15: 1.6133321 | H15: 0.0011519425 | I15: 0.00023433839 | J15: Summe aus Gesamt ID 08_32_02_003_02 ("Gesamtwert", ohne biogene CO2-Emissionen) und ID XX_00_02_003_02 (biogene CO2-Emissionen)
A17: Zusammensetzung der IDs
A18: 5 Stellen in dieser Version der Emissionsfaktorenliste:
A19: XX_XX_XX_XXX_XX
A20: 1. Stelle: 01_XX_XX_XXX_XX
A21: - Blattnummer
A22: - Außerhalb der Scopes: XX
A24: 2. Stelle: XX_10_XX_XXX_XX
A25: - Scopezuordnung
A26: 10 | B26: Scope 1 - direkte Emissionen
A27: 20 | B27: Scope 2 - direkte Emissionen
A28: 31 | B28: Scope 3 - nur Vorkette
A29: 32 | B29: Scope 3 - Gesamt
A30: 00 | B30: Außerhalb der Scopes
A32: 3. Stelle: XX_XX_01_XXX_XX
A33: - Faktorengruppe
A34: z. B. 01 | B34: Stationäre Verbrennung - Erneuerbare Brennstoffe
A35: z.B. 02 | B35: Stationäre Verbrennung - Fossile Brennstoffe
A37: 4. Stelle: XX_XX_XX_001_XX
A38: - laufende Nummer pro Eintrag (z.B. Brennstoff)
A40: 5. Stelle: XX_XX_XX_XXX_01
A41: - Einheit
A42: kWh | B42: 01
A43: l | B43: 02
A44: kg | B44: 03
A45: t | B45: 04
A46: m³ | B46: 05
A47: km | B47: 06
...

Sheet 01_Stationäre_Verbrennung
A1: 01 Stationäre Verbrennung | C1: Scope | D1: 1
A3: Biogene und fossile Brennstoffe ohne Vorketten
A4: Anmerkungen: Die Emissionsfaktoren beziehen sich auf die stationäre Verbrennung basierend auf den Endenergieverbrauch zur Wärmebereitstellung. Die Angaben in kWh entsprechen, wenn nicht anders angegeben, dem unteren Heizwert. Die angegebenen Emissionsfaktoren von biogenen Brennstoffen werden abzüglich des CO2-Anteils aus der Verbrennung ausgewiesen. Für die Berücksichtigung der Emissionen aus der Verbrennung müssen die hier aufgeführten Werte mit den Werten des Blattes "Außerhalb der Scopes" kombiniert werden.
B5: Der Emissionsfaktor (EF) für Erdgas ist in der benannten Quelle auf den unteren Heizwert bezogen. In den Erdgas Abrechnungen der Versorger sind die Energiemengen auf Brennwert bezogen. Für die Umrechnung der Werte für Erdgas von Heizwert auf Brennwert wurde der folgende Umrechnungsfaktor genutzt: 0,903; Beispielrechnung: 0,2029kg CO2e/kWh*0,903=0,1833kg CO2e/kWh.
A6: ID | B6: Scope | C6: Level 1 | D6: Level 2 | E6: Level 3 | F6: Level 4 | G6: Level 5 | H6: Einheit | I6: kg CO2e | J6: kg CO2 | K6: kg CH4 | L6: kg N2O | M6: Bezugsjahr | N6: Veröffentlichungsjahr | O6: Quelle | P6: Anmerkungen
A7: 01_10_01_001_01 | B7: Scope 1 | C7: Stationäre Verbrennung | D7: erneuerbare Brennstoffe | E7: Biodiesel | H7: kWh | I7: 0.0029224419 | K7: 4.7488025e-06 | L7: 1.0526322e-05 | M7: 2024 | N7: 2025 | O7: Emissionsbilanz erneuerbarer Energieträger (Lauf et al. 2026) | P7: Der Wert bezieht sich auf die Wärmebereitstellung, nicht auf die Nutzung im Verkehrsbereich.
A8: 01_10_01_001_02 | B8: Scope 1 | C8: Stationäre Verbrennung | D8: erneuerbare Brennstoffe | E8: Biodiesel | H8: l | I8: 0.026574509 | K8: 4.3182072e-05 | L8: 9.5718534e-05 | M8: 2024 | N8: 2025 | O8: Berechenbar mittels Emissionsbilanz erneuerbarer Energieträger (Lauf et al. 2026) | P8: Der Wert bezieht sich auf die Wärmebereitstellung, nicht auf die Nutzung im Verkehrsbereich.
A9: 01_10_01_001_04 | B9: Scope 1 | C9: Stationäre Verbrennung | D9: erneuerbare Brennstoffe | E9: Biodiesel | H9: t | I9: 30.232662 | K9: 0.049126362 | L9: 0.10889481 | M9: 2024 | N9: 2025 | O9: Berechenbar mittels Emissionsbilanz erneuerbarer Energieträger (Lauf et al. 2026) | P9: Der Wert bezieht sich auf die Wärmebereitstellung, nicht auf die Nutzung im Verkehrsbereich.
A10: 01_10_01_002_01 | B10: Scope 1 | C10: Stationäre Verbrennung | D10: erneuerbare Brennstoffe | E10: Biogas | H10: kWh | I10: 0.051037559 | K10: 0.0017703 | L10: 5.544e-06 | M10: 2024 | N10: 2025 | O10: Emissionsbilanz erneuerbarer Energieträger (Lauf et al. 2026)
A11: 01_10_01_002_05 | B11: Scope 1 | C11: Stationäre Verbrennung | D11: erneuerbare Brennstoffe | E11: Biogas | H11: m³ | I11: 0.28354426 | K11: 0.0098350784 | L11: 3.0800246e-05 | M11: 2024 | N11: 2025 | O11: Berechenbar mittels Emissionsbilanz erneuerbarer Energieträger (Lauf et al. 2026)
A12: 01_10_01_003_01 | B12: Scope 1 | C12: Stationäre Verbrennung | D12: erneuerbare Brennstoffe | E12: Biomethan | H12: kWh | I12: 0.028292148 | K12: 0.000978066 | L12: 3.42e-06 | M12: 2024 | N12: 2025 | O12: Emissionsbilanz erneuerbarer Energieträger (Lauf et al. 2026) | P12: Der Wert bezieht sich auf die Wärmebereitstellung, nicht auf die Nutzung im Verkehrsbereich.
A13: 01_10_01_003_02 | B13: Scope 1 | C13: Stationäre Verbrennung | D13: erneuerbare Brennstoffe | E13: Biomethan | H13: l | I13: =I12*Umrechnungsfaktoren!$H$20 -> 0.26165522 | K13: =K12*Umrechnungsfaktoren!$H$20 -> 0.0090454804 | L13: =L12*Umrechnungsfaktoren!$H$20 -> 3.16293e-05 | M13: 2024 | N13: 2025 | O13: Berechenbar mittels Emissionsbilanz erneuerbarer Energieträger (Lauf et al. 2026) | P13: Der Wert bezieht sich auf die Wärmebereitstellung, nicht auf die Nutzung im Verkehrsbereich.
A14: 01_10_01_003_04 | B14: Scope 1 | C14: Stationäre Verbrennung | D14: erneuerbare Brennstoffe | E14: Biomethan | H14: t | I14: =I12*Umrechnungsfaktoren!$F$20 -> 365.44025 | K14: =K12*Umrechnungsfaktoren!$F$20 -> 12.633352 | L14: =L12*Umrechnungsfaktoren!$F$20 -> 0.044175 | M14: 2024 | N14: 2025 | O14: Berechenbar mittels Emissionsbilanz erneuerbarer Energieträger (Lauf et al. 2026) | P14: Der Wert bezieht sich auf die Wärmebereitstellung, nicht auf die Nutzung im Verkehrsbereich.
A15: 01_10_01_004_01 | B15: Scope 1 | C15: Stationäre Verbrennung | D15: erneuerbare Brennstoffe | E15: Deponiegas | H15: kWh | I15: 0.032946984 | K15: 0.001124208 | L15: 5.544e-06 | M15: 2024 | N15: 2025 | O15: Emissionsbilanz erneuerbarer Energieträger (Lauf et al. 2026)
A16: 01_10_01_004_05 | B16: Scope 1 | C16: Stationäre Verbrennung | D16: erneuerbare Brennstoffe | E16: Deponiegas | H16: m³ | I16: 0.13178794 | K16: 0.004496832 | L16: 2.2176e-05 | M16: 2024 | N16: 2025 | O16: Berechenbar mittels Emissionsbilanz erneuerbarer Energieträger (Lauf et al. 2026)
A17: 01_10_01_005_01 | B17: Scope 1 | C17: Stationäre Verbrennung | D17: erneuerbare Brennstoffe | E17: Klärgas | H17: kWh | I17: 0.032946984 | K17: 0.001124208 | L17: 5.544e-06 | M17: 2024 | N17: 2025 | O17: Emissionsbilanz erneuerbarer Energieträger (Lauf et al. 2026)
A18: 01_10_01_005_05 | B18: Scope 1 | C18: Stationäre Verbrennung | D18: erneuerbare Brennstoffe | E18: Klärgas | H18: m³ | I18: 0.2040868 | K18: 0.006963794 | L18: 3.4341754e-05 | M18: 2024 | N18: 2025 | O18: Berechenbar mittels Emissionsbilanz erneuerbarer Energieträger (Lauf et al. 2026)
A19: 01_10_01_006_01 | B19: Scope 1 | C19: Stationäre Verbrennung | D19: erneuerbare Brennstoffe | E19: feste Biomasse | F19: Gemischtes Wald-Scheitholz | G19: Einzelraumfeuerung | H19: kWh | I19: 0.015179872 | K19: 0.00047873086 | L19: 6.6996545e-06 | M19: 2024 | N19: 2025 | O19: Emissionsbilanz erneuerbarer Energieträger (Lauf et al. 2026)
A20: 01_10_01_006_05 | B20: Scope 1 | C20: Stationäre Verbrennung | D20: erneuerbare Brennstoffe | E20: feste Biomasse | F20: Gemischtes Wald-Scheitholz | G20: Einzelraumfeuerung | H20: m³ | I20: 24.352943 | K20: 0.76802392 | L20: 0.0107482 | M20: 2024 | N20: 2025 | O20: Berechenbar mittels Emissionsbilanz erneuerbarer Energieträger (Lauf et al. 2026) | P20: Mittelwert aus Laubholz und Nadelholz, Bezug Raummeter Holz, 15% Wassergehalt
A21: 01_10_01_006_04 | B21: Scope 1 | C21: Stationäre Verbrennung | D21: erneuerbare Brennstoffe | E21: feste Biomasse | F21: Gemischtes Wald-Scheitholz | G21: Einzelraumfeuerung | H21: t | I21: 65.146953 | K21: 2.0545533 | L21: 0.028752684 | M21: 2024 | N21: 2025 | O21: Berechenbar mittels Emissionsbilanz erneuerbarer Energieträger (Lauf et al. 2026) | P21: Mittelwert aus Laubholz und Nadelholz, 15% Wassergehalt
A22: 01_10_01_007_01 | B22: Scope 1 | C22: Stationäre Verbrennung | D22: erneuerbare Brennstoffe | E22: feste Biomasse | F22: Gemischtes Wald-Scheitholz | G22: Kessel | H22: kWh | I22: 0.00083955063 | K22: 2.0443951e-05 | L22: 1.008e-06 | M22: 2024 | N22: 2025 | O22: Emissionsbilanz erneuerbarer Energieträger (Lauf et al. 2026)
A23: 01_10_01_007_05 | B23: Scope 1 | C23: Stationäre Verbrennung | D23: erneuerbare Brennstoffe | E23: feste Biomasse | F23: Gemischtes Wald-Scheitholz | G23: Kessel | H23: m³ | I23: 1.3468841 | K23: 0.03279806 | L23: 0.001617126 | M23: 2024 | N23: 2025 | O23: Berechenbar mittels Emissionsbilanz erneuerbarer Energieträger (Lauf et al. 2026) | P23: Mittelwert aus Laubholz und Nadelholz, Bezug Raummeter Holz, 15% Wassergehalt
A24: 01_10_01_007_04 | B24: Scope 1 | C24: Stationäre Verbrennung | D24: erneuerbare Brennstoffe | E24: feste Biomasse | F24: Gemischtes Wald-Scheitholz | G24: Kessel | H24: t | I24: 3.6030715 | K24: 0.087738624 | L24: 0.004326 | M24: 2024 | N24: 2025 | O24: Berechenbar mittels Emissionsbilanz erneuerbarer Energieträger (Lauf et al. 2026) | P24: Mittelwert aus Laubholz und Nadelholz, 15% Wassergehalt
A25: 01_10_01_008_01 | B25: Scope 1 | C25: Stationäre Verbrennung | D25: erneuerbare Brennstoffe | E25: feste Biomasse | F25: Altholz / Holzreste | G25: Industrielle Feuerung | H25: kWh | I25: 0.0033983741 | K25: 3.1898293e-05 | L25: 9.4536675e-06 | M25: 2024 | N25: 2025 | O25: Emissionsbilanz erneuerbarer Energieträger (Lauf et al. 2026)
A26: 01_10_01_008_05 | B26: Scope 1 | C26: Stationäre Verbrennung | D26: erneuerbare Brennstoffe | E26: feste Biomasse | F26: Altholz / Holzreste | G26: Industrielle Feuerung | H26: m³ | I26: 7.0771141 | K26: 0.066428196 | L26: 0.019687262 | M26: 2024 | N26: 2025 | O26: Berechenbar mittels Emissionsbilanz erneuerbarer Energieträger (Lauf et al. 2026)
A27: 01_10_01_008_04 | B27: Scope 1 | C27: Stationäre Verbrennung | D27: erneuerbare Brennstoffe | E27: feste Biomasse | F27: Altholz / Holzreste | G27: Industrielle Feuerung | H27: t | I27: 13.876694 | K27: 0.13025137 | L27: 0.038602475 | M27: 2024 | N27: 2025 | O27: Berechenbar mittels Emissionsbilanz erneuerbarer Energieträger (Lauf et al. 2026)
A28: 01_10_01_009_01 | B28: Scope 1 | C28: Stationäre Verbrennung | D28: erneuerbare Brennstoffe | E28: feste Biomasse | F28: Pellets | H28: kWh | I28: 0.00036862977 | K28: 1.7896112e-06 | L28: 1.2019647e-06 | M28: 2024 | N28: 2025 | O28: Emissionsbilanz erneuerbarer Energieträger (Lauf et al. 2026)
A29: 01_10_01_009_05 | B29: Scope 1 | C29: Stationäre Verbrennung | D29: erneuerbare Brennstoffe | E29: feste Biomasse | F29: Pellets | H29: m³ | I29: 1.1381444 | K29: 0.0055254245 | L29: 0.0037110662 | M29: 2024 | N29: 2025 | O29: Berechenbar mittels Emissionsbilanz erneuerbarer Energieträger (Lauf et al. 2026)
A30: 01_10_01_009_04 | B30: Scope 1 | C30: Stationäre Verbrennung | D30: erneuerbare Brennstoffe | E30: feste Biomasse | F30: Pellets | H30: t | I30: 1.7509914 | K30: 0.0085006531 | L30: 0.0057093326 | M30: 2024 | N30: 2025 | O30: Berechenbar mittels Emissionsbilanz erneuerbarer Energieträger (Lauf et al. 2026)
A31: 01_10_02_001_01 | B31: Scope 1 | C31: Stationäre Verbrennung | D31: fossile Brennstoffe | E31: Braunkohle | F31: Briketts | H31: kWh | I31: 0.38198781 | J31: 0.35312378 | K31: 0.000853632 | L31: 1.872576e-05 | M31: 2024 | N31: 2025 | O31: Emissionsbilanz erneuerbarer Energieträger (Lauf et al. 2026)
A32: 01_10_02_001_04 | B32: Scope 1 | C32: Stationäre Verbrennung | D32: fossile Brennstoffe | E32: Braunkohle | F32: Briketts | H32: t | I32: 2038.5416 | J32: 1884.5039 | K32: 4.5555494 | L32: 0.099933139 | M32: 2024 | N32: 2025 | O32: Berechenbar mittels Emissionsbilanz erneuerbarer Energieträger (Lauf et al. 2026)
A33: 01_10_02_002_01 | B33: Scope 1 | C33: Stationäre Verbrennung | D33: fossile Brennstoffe | E33: flüssige Brennstoffe | F33: Heizöl, leicht | H33: kWh | I33: 0.26699799 | J33: 0.266472 | K33: 1.6524e-07 | L33: 1.9674e-06 | M33: 2024 | N33: 2025 | O33: Emissionsbilanz erneuerbarer Energieträger (Lauf et al. 2026)
A34: 01_10_02_002_02 | B34: Scope 1 | C34: Stationäre Verbrennung | D34: fossile Brennstoffe | E34: flüssige Brennstoffe | F34: Heizöl, leicht | H34: l | I34: 2.6208878 | J34: 2.6157247 | K34: 1.6220179e-06 | L34: 1.9312261e-05 | M34: 2024 | N34: 2025 | O34: Berechenbar mittels Emissionsbilanz erneuerbarer Energieträger (Lauf et al. 2026)
A35: 01_10_02_002_04 | B35: Scope 1 | C35: Stationäre Verbrennung | D35: fossile Brennstoffe | E35: flüssige Brennstoffe | F35: Heizöl, leicht | H35: t | I35: 3157.6962 | J35: 3151.4755 | K35: 0.0019542384 | L35: 0.023267784 | M35: 2024 | N35: 2025 | O35: Berechenbar mittels Emissionsbilanz erneuerbarer Energieträger (Lauf et al. 2026)
A36: 01_10_02_003_01 | B36: Scope 1 | C36: Stationäre Verbrennung | D36: fossile Brennstoffe | E36: flüssige Brennstoffe | F36: Dieselkraftstoff | H36: kWh | I36: 0.27123483 | J36: 0.26753447 | K36: 1.2890045e-05 | L36: 1.2601632e-05 | M36: 2024 | N36: 2025 | O36: Emissionsbilanz erneuerbarer Energieträger (Lauf et al. 2026)
A37: 01_10_02_003_02 | B37: Scope 1 | C37: Stationäre Verbrennung | D37: fossile Brennstoffe | E37: flüssige Brennstoffe | F37: Dieselkraftstoff | H37: l | I37: 2.686194 | J37: 2.6495473 | K37: 0.0001276575 | L37: 0.00012480119 | M37: 2024 | N37: 2025 | O37: Berechenbar mittels Emissionsbilanz erneuerbarer Energieträger (Lauf et al. 2026)
A38: 01_10_02_003_04 | B38: Scope 1 | C38: Stationäre Verbrennung | D38: fossile Brennstoffe | E38: flüssige Brennstoffe | F38: Dieselkraftstoff | H38: t | I38: 3228.5986 | J38: 3184.552 | K38: 0.1534345 | L38: 0.15000142 | M38: 2024 | N38: 2025 | O38: Berechenbar mittels Emissionsbilanz erneuerbarer Energieträger (Lauf et al. 2026)
A39: 01_10_02_004_01 | B39: Scope 1 | C39: Stationäre Verbrennung | D39: fossile Brennstoffe | E39: Gase | F39: Erdgas (Heizwert) | H39: kWh | I39: 0.20293791 | J39: 0.20239567 | K39: 1.08e-05 | L39: 9.0504e-07 | M39: 2024 | N39: 2025 | O39: Emissionsbilanz erneuerbarer Energieträger (Lauf et al. 2026)
A40: 01_10_02_004_05 | B40: Scope 1 | C40: Stationäre Verbrennung | D40: fossile Brennstoffe | E40: Gase | F40: Erdgas | H40: m³ | I40: 1.9832716 | J40: 1.9779724 | K40: 0.00010554624 | L40: 8.8447749e-06 | M40: 2024 | N40: 2025 | O40: Berechenbar mittels Emissionsbilanz erneuerbarer Energieträger (Lauf et al. 2026)
A41: 01_10_02_005_01 | B41: Scope 1 | C41: Stationäre Verbrennung | D41: fossile Brennstoffe | E41: Gase | F41: Erdgas (Brennwert) | H41: kWh | I41: 0.18325293 | J41: 0.18276329 | K41: 9.7524e-06 | L41: 8.1725112e-07 | M41: 2024 | N41: 2025 | O41: Berechenbar mittels Emissionsbilanz erneuerbarer Energieträger (Lauf et al. 2026)
...

Sheet 02_Mobile_Verbrennung
A1: 02 Mobile Verbrennung | C1: Scope | D1: 1
A3: Biogene und fossile Brennstoffe für den Einsatz in mobilen Geräten, nach Kraftstoffverbrauch sowie nach nach Strecke/Fahrzeug für Güterfahrzeuge und Personenfahrzeuge ohne Vorketten
A4: Anmerkungen: Bei der Bilanzierung einer Fahrt ist entweder der Ansatz über die Strecke und den Fahrzeugtyp oder über den Kraftstoffverbrauch zu wählen. Die Emissionsfaktoren für den Kraftstoffverbrauch sind "Tank-to-wheel-Werte".
A5: ID | B5: Scope | C5: Level 1 | D5: Level 2 | E5: Level 3 | F5: Level 4 | G5: Level 5 | H5: Level 6 | I5: Level 7 | J5: Level 8 | K5: Einheit | L5: kg CO2e | M5: kg CO2 | N5: kg CH4 | O5: kg N2O | P5: Bezugsjahr | Q5: Veröffentlichungsjahr | R5: Quelle | S5: Anmerkungen
A6: 02_10_01_001_01 | B6: Scope 1 | C6: Mobile Verbrennung | D6: nach Kraftstoffverbrauch | E6: Benzin/Ottokraftstoff | K6: kWh | L6: 0.26305029 | M6: 0.26203168 | N6: 2.5641935e-05 | O6: 1.1344932e-06 | P6: 2024 | Q6: 2025 | R6: TREMOD 6.71 Transport Emission Model | S6: 100 % fossiler Kraftstoff
A7: 02_10_01_001_02 | B7: Scope 1 | C7: Mobile Verbrennung | D7: nach Kraftstoffverbrauch | E7: Benzin/Ottokraftstoff | K7: l | L7: 2.3607964 | M7: 2.3516547 | N7: 0.00023012857 | O7: 1.0181732e-05 | P7: 2024 | Q7: 2025 | R7: TREMOD 6.71 Transport Emission Model | S7: 100 % fossiler Kraftstoff
A8: 02_10_01_001_04 | B8: Scope 1 | C8: Mobile Verbrennung | D8: nach Kraftstoffverbrauch | E8: Benzin/Ottokraftstoff | K8: t | L8: 3181.6663 | M8: 3169.3459 | N8: 0.31014633 | O8: 0.01372201 | P8: 2024 | Q8: 2025 | R8: TREMOD 6.71 Transport Emission Model | S8: 100 % fossiler Kraftstoff
A9: 02_10_01_002_01 | B9: Scope 1 | C9: Mobile Verbrennung | D9: nach Kraftstoffverbrauch | E9: Biodiesel | K9: kWh | L9: 0.017822742 | M9: 0.0140184 | N9: 6.7553461e-06 | O9: 1.3642236e-05 | P9: 2024 | Q9: 2025 | R9: TREMOD 6.71 Transport Emission Model
A10: 02_10_01_002_02 | B10: Scope 1 | C10: Mobile Verbrennung | D10: nach Kraftstoffverbrauch | E10: Biodiesel | K10: l | L10: 0.16206674 | M10: 0.12747289 | N10: 6.1428085e-05 | O10: 0.00012405233 | P10: 2024 | Q10: 2025 | R10: TREMOD 6.71 Transport Emission Model
A11: 02_10_01_002_04 | B11: Scope 1 | C11: Mobile Verbrennung | D11: nach Kraftstoffverbrauch | E11: Biodiesel | K11: t | L11: 184.37627 | M11: 145.02035 | N11: 0.069884056 | O11: 0.14112893 | P11: 2024 | Q11: 2025 | R11: TREMOD 6.71 Transport Emission Model
A12: 02_10_01_003_01 | B12: Scope 1 | C12: Mobile Verbrennung | D12: nach Kraftstoffverbrauch | E12: Bioethanol | K12: kWh | L12: 0.018202557 | M12: 0.017183942 | N12: 2.5641935e-05 | O12: 1.1344932e-06 | P12: 2024 | Q12: 2025 | R12: TREMOD 6.71 Transport Emission Model
A13: 02_10_01_003_02 | B13: Scope 1 | C13: Mobile Verbrennung | D13: nach Kraftstoffverbrauch | E13: Bioethanol | K13: l | L13: 0.10648405 | M13: 0.1005252 | N13: 0.00015000404 | O13: 6.6367285e-06 | P13: 2024 | Q13: 2025 | R13: TREMOD 6.71 Transport Emission Model
A14: 02_10_01_003_04 | B14: Scope 1 | C14: Mobile Verbrennung | D14: nach Kraftstoffverbrauch | E14: Bioethanol | K14: t | L14: 134.78994 | M14: 127.24709 | N14: 0.18987853 | O14: 0.0084009222 | P14: 2024 | Q14: 2025 | R14: TREMOD 6.71 Transport Emission Model
A15: 02_10_01_004_01 | B15: Scope 1 | C15: Mobile Verbrennung | D15: nach Kraftstoffverbrauch | E15: Biomethan | K15: kWh | L15: 0.0030455601 | N15: 0.0001066403 | O15: 2.2502534e-07 | P15: 2024 | Q15: 2025 | R15: TREMOD 6.71 Transport Emission Model
A16: 02_10_01_004_02 | B16: Scope 1 | C16: Mobile Verbrennung | D16: nach Kraftstoffverbrauch | E16: Biomethan | K16: l | L16: 0.028166355 | N16: 0.00098624503 | O16: 2.0811093e-06 | P16: 2024 | Q16: 2025 | R16: TREMOD 6.71 Transport Emission Model
A17: 02_10_01_004_04 | B17: Scope 1 | C17: Mobile Verbrennung | D17: nach Kraftstoffverbrauch | E17: Biomethan | K17: t | L17: 39.338484 | N17: 1.3774372 | O17: 0.0029065773 | P17: 2024 | Q17: 2025 | R17: TREMOD 6.71 Transport Emission Model
A18: 02_10_01_005_01 | B18: Scope 1 | C18: Mobile Verbrennung | D18: nach Kraftstoffverbrauch | E18: Dieselkraftstoff | K18: kWh | L18: 0.27029985 | M18: 0.26649551 | N18: 6.7553461e-06 | O18: 1.3642236e-05 | P18: 2024 | Q18: 2025 | R18: TREMOD 6.71 Transport Emission Model | S18: 100 % fossiler Kraftstoff
A19: 02_10_01_005_02 | B19: Scope 1 | C19: Mobile Verbrennung | D19: nach Kraftstoffverbrauch | E19: Dieselkraftstoff | K19: l | L19: 2.6769344 | M19: 2.6392578 | N19: 6.6902066e-05 | O19: 0.00013510688 | P19: 2024 | Q19: 2025 | R19: TREMOD 6.71 Transport Emission Model | S19: 100 % fossiler Kraftstoff
A20: 02_10_01_005_04 | B20: Scope 1 | C20: Mobile Verbrennung | D20: nach Kraftstoffverbrauch | E20: Dieselkraftstoff | K20: t | L20: 3217.4692 | M20: 3172.1849 | N20: 0.080411137 | O20: 0.16238808 | P20: 2024 | Q20: 2025 | R20: TREMOD 6.71 Transport Emission Model | S20: 100 % fossiler Kraftstoff
A21: 02_10_01_006_01 | B21: Scope 1 | C21: Mobile Verbrennung | D21: nach Kraftstoffverbrauch | E21: Erdgas (CNG) | K21: kWh | L21: 0.20425528 | M21: 0.20286692 | N21: 4.9584197e-05 | O21: 0 | P21: 2024 | Q21: 2025 | R21: TREMOD 6.71 Transport Emission Model
A22: 02_10_01_006_05 | B22: Scope 1 | C22: Mobile Verbrennung | D22: nach Kraftstoffverbrauch | E22: Erdgas (CNG) | K22: m³ | L22: 1.8890209 | M22: 1.8761809 | N22: 0.00045857118 | O22: 0 | P22: 2024 | Q22: 2025 | R22: TREMOD 6.71 Transport Emission Model
A23: 02_10_01_006_04 | B23: Scope 1 | C23: Mobile Verbrennung | D23: nach Kraftstoffverbrauch | E23: Erdgas (CNG) | K23: t | L23: 2638.2974 | M23: 2620.3644 | N23: 0.64046254 | O23: 0 | P23: 2024 | Q23: 2025 | R23: TREMOD 6.71 Transport Emission Model
A24: 02_10_01_007_01 | B24: Scope 1 | C24: Mobile Verbrennung | D24: nach Kraftstoffverbrauch | E24: Flugbenzin (AvGas) | K24: kWh | L24: 0.2610529 | M24: 0.25647476 | N24: 8.5208347e-05 | O24: 8.2728193e-06 | P24: 2024 | Q24: 2025 | R24: TREMOD 6.71 Transport Emission Model
A25: 02_10_01_007_02 | B25: Scope 1 | C25: Mobile Verbrennung | D25: nach Kraftstoffverbrauch | E25: Flugbenzin (AvGas) | K25: l | L25: 2.3414 | M25: 2.3004 | N25: 0.000764 | O25: 7.42e-05 | P25: 2024 | Q25: 2025 | R25: TREMOD 6.71 Transport Emission Model
A26: 02_10_01_007_04 | B26: Scope 1 | C26: Mobile Verbrennung | D26: nach Kraftstoffverbrauch | E26: Flugbenzin (AvGas) | K26: t | L26: 3155.5494 | M26: 3100.2099 | N26: 1.0299796 | O26: 0.1 | P26: 2024 | Q26: 2025 | R26: TREMOD 6.71 Transport Emission Model
A27: 02_10_01_008_01 | B27: Scope 1 | C27: Mobile Verbrennung | D27: nach Kraftstoffverbrauch | E27: Flüssigerdgas (LNG) | K27: kWh | L27: 0.20669241 | M27: 0.20286692 | N27: 0.00013662456 | O27: 0 | P27: 2024 | Q27: 2025 | R27: TREMOD 6.71 Transport Emission Model
A28: 02_10_01_008_05 | B28: Scope 1 | C28: Mobile Verbrennung | D28: nach Kraftstoffverbrauch | E28: Flüssigerdgas (LNG) | K28: m³ | L28: 1.9115603 | M28: 1.8761809 | N28: 0.0012635495 | O28: 0 | P28: 2024 | Q28: 2025 | R28: TREMOD 6.71 Transport Emission Model
A29: 02_10_01_008_04 | B29: Scope 1 | C29: Mobile Verbrennung | D29: nach Kraftstoffverbrauch | E29: Flüssigerdgas (LNG) | K29: t | L29: 2669.777 | M29: 2620.3644 | N29: 1.7647339 | O29: 0 | P29: 2024 | Q29: 2025 | R29: TREMOD 6.71 Transport Emission Model
A30: 02_10_01_009_01 | B30: Scope 1 | C30: Mobile Verbrennung | D30: nach Kraftstoffverbrauch | E30: Flüssiggas (LPG) | K30: kWh | L30: 0.23977541 | M30: 0.23880059 | N30: 6.8221481e-06 | O30: 2.9577318e-06 | P30: 2024 | Q30: 2025 | R30: TREMOD 6.71 Transport Emission Model
A31: 02_10_01_009_02 | B31: Scope 1 | C31: Mobile Verbrennung | D31: nach Kraftstoffverbrauch | E31: Flüssiggas (LPG) | K31: l | L31: 1.8621758 | M31: 1.854605 | N31: 5.2983076e-05 | O31: 2.2970731e-05 | P31: 2024 | Q31: 2025 | R31: TREMOD 6.71 Transport Emission Model
A32: 02_10_01_009_04 | B32: Scope 1 | C32: Mobile Verbrennung | D32: nach Kraftstoffverbrauch | E32: Flüssiggas (LPG) | K32: t | L32: 3103.6263 | M32: 3091.0083 | N32: 0.088305127 | O32: 0.038284552 | P32: 2024 | Q32: 2025 | R32: TREMOD 6.71 Transport Emission Model
... A37: 02_10_01_011_04 | B37: Scope 1 | C37: Mobile Verbrennung | D37: nach Kraftstoffverbrauch | E37: Schweröl (HFO) | K37: t | L37: 3183.4237 | M37: 3138.7204 | N37: 0.141985 | O37: 0.13809978 | P37: 2024 | Q37: 2025 | R37: Emissionsinventar/BSH-Modell EMMA, AGEB Energiebilanz
A38: 02_10_02_001_06 | B38: Scope 1 | C38: Mobile Verbrennung | D38: nach Strecke/Fahrzeug | E38: Güterfahrzeuge | F38: Leichtes Nutzfahrzeug (<3,5t) | G38: Benzinmotor | H38: Unbekannter Straßentyp/Durchschnitt | K38: km | L38: 0.22232291 | M38: 0.22099772 | N38: 3.0378526e-05 | O38: 1.790906e-06 | P38: 2024 | Q38: 2025 | R38: TREMOD 6.71B Transport Emission Model
A39: 02_10_02_002_06 | B39: Scope 1 | C39: Mobile Verbrennung | D39: nach Strecke/Fahrzeug | E39: Güterfahrzeuge | F39: Leichtes Nutzfahrzeug (<3,5t) | G39: Dieselmotor | H39: Unbekannter Straßentyp/Durchschnitt | K39: km | L39: 0.24926584 | M39: 0.24639779 | N39: 8.6866921e-06 | O39: 9.904971e-06 | P39: 2024 | Q39: 2025 | R39: TREMOD 6.71B Transport Emission Model
A40: 02_10_02_004_06 | B40: Scope 1 | C40: Mobile Verbrennung | D40: nach Strecke/Fahrzeug | E40: Güterfahrzeuge | F40: Leichtes Nutzfahrzeug (<3,5t) | G40: Unbekannter Antrieb/Durchschnitt | H40: Unbekannter Straßentyp/Durchschnitt | K40: km | L40: 0.24326306 | M40: 0.24052772 | N40: 9.7372611e-06 | O40: 9.2931967e-06 | P40: 2024 | Q40: 2025 | R40: TREMOD 6.71B Transport Emission Model
A41: 02_10_02_005_06 | B41: Scope 1 | C41: Mobile Verbrennung | D41: nach Strecke/Fahrzeug | E41: Güterfahrzeuge | F41: Schweres Nutzfahrzeug (>3,5t) | G41: Durchschnittliche Größe/unbekannt | H41: Unbekannter Straßentyp/Durchschnitt | I41: Durchschnittliche Beladung | J41: Ungekühlt | K41: km | L41: 0.70211993 | M41: 0.69049508 | N41: 5.6967613e-06 | O41: 4.3265451e-05 | P41: 2024 | Q41: 2025 | R41: TREMOD 6.71B Transport Emission Model
A42: 02_10_02_006_06 | B42: Scope 1 | C42: Mobile Verbrennung | D42: nach Strecke/Fahrzeug | E42: Güterfahrzeuge | F42: Schweres Nutzfahrzeug (>3,5t) | G42: Sattel/Lastzug (<28t), Diesel | H42: Unbekannter Straßentyp/Durchschnitt | I42: Durchschnittliche Beladung | J42: Ungekühlt | K42: km | L42: 0.57001169 | M42: 0.56192045 | N42: 1.4190422e-06 | O42: 3.0383051e-05 | P42: 2024 | Q42: 2025 | R42: TREMOD 6.71B Transport Emission Model
A43: 02_10_02_007_06 | B43: Scope 1 | C43: Mobile Verbrennung | D43: nach Strecke/Fahrzeug | E43: Güterfahrzeuge | F43: Schweres Nutzfahrzeug (>3,5t) | G43: Sattel/Lastzug (28-34t), Diesel | H43: Unbekannter Straßentyp/Durchschnitt | I43: Durchschnittliche Beladung | J43: Ungekühlt | K43: km | L43: 0.71836389 | M43: 0.70582685 | N43: 1.0823192e-06 | O43: 4.7195196e-05 | P43: 2024 | Q43: 2025 | R43: TREMOD 6.71B Transport Emission Model
A44: 02_10_02_009_06 | B44: Scope 1 | C44: Mobile Verbrennung | D44: nach Strecke/Fahrzeug | E44: Güterfahrzeuge | F44: Schweres Nutzfahrzeug (>3,5t) | G44: Sattel/Lastzug unbekannte Größe, CNG | H44: Unbekannter Straßentyp/Durchschnitt | I44: Durchschnittliche Beladung | J44: Ungekühlt | K44: km | L44: 0.10921737 | M44: 0.1052855 | N44: 0.00014042402 | O44: 0 | P44: 2024 | Q44: 2025 | R44: TREMOD 6.71B Transport Emission Model
A45: 02_10_02_010_06 | B45: Scope 1 | C45: Mobile Verbrennung | D45: nach Strecke/Fahrzeug | E45: Güterfahrzeuge | F45: Schweres Nutzfahrzeug (>3,5t) | G45: Sattel/Lastzug unbekannte Größe, LNG | H45: Unbekannter Straßentyp/Durchschnitt | I45: Durchschnittliche Beladung | J45: Ungekühlt | K45: km | L45: 0.10453534 | M45: 0.093500355 | N45: 0.0003941067 | O45: 0 | P45: 2024 | Q45: 2025 | R45: TREMOD 6.71B Transport Emission Model
...

Sheet 03_Industrieprozesse
A1: 03 Industrieprozesse | C1: Scope | D1: 1
A3: Emissionsfaktoren von Industrieprozessen
A4: Anmerkung: Die Angaben beziehen sich nur auf die direkten Emissionen von CO2 aus dem jeweiligen Industrieprozess. Die funktionelle Einheit (t) bezieht sich auf den Rohstoff (z.B. Verwendung von Soda) oder das Produkt.
A5: ID | B5: Scope | C5: Level 1 | D5: Level 2 | E5: Einheit | F5: kg CO2 | G5: Bezugsjahr | H5: Publikationsjahr | I5: Quelle | J5: Anmerkungen
A6: 03_10_01_001_04 | B6: Scope 1 | C6: Industrieprozesse | D6: Produktion von Zementklinker | E6: t | F6: 530 | G6: 2024 | H6: 2026 | I6: Tabellarische Aufstellung der abgeleiteten Emissionsfaktoren für CO2: Energie & Industrieprozesse (2026)
A7: 03_10_01_002_04 | B7: Scope 1 | C7: Industrieprozesse | D7: Produktion von Branntkalk | E7: t | F7: 746 | G7: 2024 | H7: 2026 | I7: Tabellarische Aufstellung der abgeleiteten Emissionsfaktoren für CO2: Energie & Industrieprozesse (2026)
A8: 03_10_01_003_04 | B8: Scope 1 | C8: Industrieprozesse | D8: Produktion von Dolomitkalk | E8: t | F8: 867 | G8: 2024 | H8: 2026 | I8: Tabellarische Aufstellung der abgeleiteten Emissionsfaktoren für CO2: Energie & Industrieprozesse (2026)
A9: 03_10_01_004_04 | B9: Scope 1 | C9: Industrieprozesse | D9: Produktion von Behälterglas | E9: t | F9: 193 | G9: 2024 | H9: 2026 | I9: Tabellarische Aufstellung der abgeleiteten Emissionsfaktoren für CO2: Energie & Industrieprozesse (2026)
A10: 03_10_01_005_04 | B10: Scope 1 | C10: Industrieprozesse | D10: Produktion von Flachglas | E10: t | F10: 208 | G10: 2024 | H10: 2026 | I10: Tabellarische Aufstellung der abgeleiteten Emissionsfaktoren für CO2: Energie & Industrieprozesse (2026)
A11: 03_10_01_006_04 | B11: Scope 1 | C11: Industrieprozesse | D11: Produktion von Wirtschaftsglas | E11: t | F11: 120 | G11: 2024 | H11: 2026 | I11: Tabellarische Aufstellung der abgeleiteten Emissionsfaktoren für CO2: Energie & Industrieprozesse (2026)
A12: 03_10_01_007_04 | B12: Scope 1 | C12: Industrieprozesse | D12: Produktion von Spezialglas | E12: t | F12: 113 | G12: 2024 | H12: 2026 | I12: Tabellarische Aufstellung der abgeleiteten Emissionsfaktoren für CO2: Energie & Industrieprozesse (2026)
A13: 03_10_01_008_04 | B13: Scope 1 | C13: Industrieprozesse | D13: Produktion von Glasfasern | E13: t | F13: 198 | G13: 2024 | H13: 2026 | I13: Tabellarische Aufstellung der abgeleiteten Emissionsfaktoren für CO2: Energie & Industrieprozesse (2026)
A14: 03_10_01_009_04 | B14: Scope 1 | C14: Industrieprozesse | D14: Produktion von Steinwolle | E14: t | F14: 299 | G14: 2024 | H14: 2026 | I14: Tabellarische Aufstellung der abgeleiteten Emissionsfaktoren für CO2: Energie & Industrieprozesse (2026)
A15: 03_10_01_010_04 | B15: Scope 1 | C15: Industrieprozesse | D15: Produktion von Glas | E15: t | F15: 114.19087 | G15: 2024 | H15: 2026 | I15: Tabellarische Aufstellung der abgeleiteten Emissionsfaktoren für CO2: Energie & Industrieprozesse (2026) | J15: über alle Glasarten: CO2-EF = (EM-Summe inkl. Altglaseinsatz)/ ARa
A16: 03_10_01_011_04 | B16: Scope 1 | C16: Industrieprozesse | D16: Produktion von Keramik | E16: t | F16: 48.687777 | G16: 2024 | H16: 2026 | I16: Tabellarische Aufstellung der abgeleiteten Emissionsfaktoren für CO2: Energie & Industrieprozesse (2026) | J16: über alle Produkte: CO2-EF = EM-Summe/ ARa
A17: 03_10_01_012_04 | B17: Scope 1 | C17: Industrieprozesse | D17: Verwendung von Soda | E17: t | F17: 415 | G17: 2024 | H17: 2026 | I17: Tabellarische Aufstellung der abgeleiteten Emissionsfaktoren für CO2: Energie & Industrieprozesse (2026)
A18: 03_10_01_013_04 | B18: Scope 1 | C18: Industrieprozesse | D18: Produktion von Ammoniak | E18: t | F18: 1353.99 | G18: 2024 | H18: 2026 | I18: Tabellarische Aufstellung der abgeleiteten Emissionsfaktoren für CO2: Energie & Industrieprozesse (2026) | J18: CO2-EF = (EM - Recovery amount)/ ARa
A19: 03_10_01_014_04 | B19: Scope 1 | C19: Industrieprozesse | D19: Petrochemie | E19: t | F19: 28 | G19: 2024 | H19: 2026 | I19: Tabellarische Aufstellung der abgeleiteten Emissionsfaktoren für CO2: Energie & Industrieprozesse (2026)
A20: 03_10_01_015_04 | B20: Scope 1 | C20: Industrieprozesse | D20: Produktion von Ruß | E20: t | F20: 1960 | G20: 2024 | H20: 2026 | I20: Tabellarische Aufstellung der abgeleiteten Emissionsfaktoren für CO2: Energie & Industrieprozesse (2026)
A21: 03_10_01_016_04 | B21: Scope 1 | C21: Industrieprozesse | D21: Produktion von Elektrostahl | E21: t | F21: 7.4 | G21: 2024 | H21: 2026 | I21: Tabellarische Aufstellung der abgeleiteten Emissionsfaktoren für CO2: Energie & Industrieprozesse (2026)
A22: 03_10_01_017_04 | B22: Scope 1 | C22: Industrieprozesse | D22: Produktion von Oxygenstahl, Kalksteineinsatz | E22: t | F22: 440 | G22: 2024 | H22: 2026 | I22: Tabellarische Aufstellung der abgeleiteten Emissionsfaktoren für CO2: Energie & Industrieprozesse (2026)
A23: 03_10_01_018_04 | B23: Scope 1 | C23: Industrieprozesse | D23: Produktion von Ferrolegierungen | E23: t | F23: 110 | G23: 2024 | H23: 2026 | I23: Tabellarische Aufstellung der abgeleiteten Emissionsfaktoren für CO2: Energie & Industrieprozesse (2026)
A24: 03_10_01_019_04 | B24: Scope 1 | C24: Industrieprozesse | D24: Produktion von Hüttenaluminium | E24: t | F24: 1367 | G24: 2024 | H24: 2026 | I24: Tabellarische Aufstellung der abgeleiteten Emissionsfaktoren für CO2: Energie & Industrieprozesse (2026)
A25: 03_10_01_020_04 | B25: Scope 1 | C25: Industrieprozesse | D25: Produktion raff. Blei | E25: t | F25: 220 | G25: 2024 | H25: 2026 | I25: Tabellarische Aufstellung der abgeleiteten Emissionsfaktoren für CO2: Energie & Industrieprozesse (2026)
A26: 03_10_01_021_04 | B26: Scope 1 | C26: Industrieprozesse | D26: Zinkproduktion: Hütten- und Umschmelzzink | E26: t | F26: 1720 | G26: 2024 | H26: 2026 | I26: Tabellarische Aufstellung der abgeleiteten Emissionsfaktoren für CO2: Energie & Industrieprozesse (2026)

Sheet 04_Kältemittel u.a.
A1: 04 Kältemittel u.a. | C1: Scope | D1: 1
A3: Treibhauspotentiale (Global Warming Potential, GWP) ausgewählter Verbindungen und deren Gemische gemäß Viertem (AR4) und Fünftem (AR5) IPCC Sachstandsbericht sowie Verordnung (EU) 2024/573 (F-Gas-VO) bezogen auf einen Zeitraum von 100 Jahren
A4: Quelle: UBA 2026, https://www.umweltbundesamt.de/sites/default/files/medien/10594/dokumente/2025-05_treibhauspotentiale_gwp_ar4_ar5_vo2024-573_homepage_deutsch.pdf
A5: Anmerkungen: Der Verlust von Kältemitteln in Kälte- und Klimaanlagen kann für die Anwendung in Scope 1 entweder anhand der Richtwerte dieses Blattes jährlich in Bilanzen berücksichtigt werden oder beim Nachfüllen anhand der eingesetzten Kältemittelmenge. Die hier aufgeführten Global Warming Potentials können bspw. in Verbindung mit den unter "Anwendungshilfe Kältemittel" prozentualen Verlustwerten für verschiedene Anlagentypen genutzt werden. Die Werte enthalten keine Emissionen aus Produktion, Transport, etc. sondern beziehen sich lediglich auf die direkte Treibhausgaswirkung der angegebenen Verbindungen/Stoffgemische
B6: Die Werte enthalten keine Emissionen aus Produktion, Transport, etc. sondern beziehen sich lediglich auf die direkte Treibhausgaswirkung der angegebenen Verbindungen/Stoffgemische.
A7: Es folgen 4 Tabellen mit GWPs für unterschiedliche Verbindungen. | B7: Gemäß F-Gas-VO beziehen sich die GWP-Werte von HFKW-Kältemitteln auf den 4. Sachstandsbericht (AR4) des IPCC.
B8: Die GWP-Werte anderer Treibhausgase beziehen sich gemäß F-Gas-VO auf den 6. Sachstandsbericht (AR6) des IPCC.
A10: Treibhauspotentiale (GWP100) teil(chlor)fluorierter und perfluorierter Kohlenwasserstoffe (HFKW, HFCKW und FKW) sowie anderer perfluorierter Verbindungen
A11: ID | B11: Industrielle Bezeichnung | C11: Chemische Bezeichnung | D11: Chemische Formel / Zusammensetzung | E11: GWP AR4 [1] [kg CO2e/kg] | F11: GWP (AR5) [3] [kg CO2e/kg] | G11: GWP F-Gas-VO [5] [kg CO2e/kg] | H11: Anmerkungen
A12: Teil(chlor) fluorierte Kohlenwasserstoffe (HFKW und HFCKW)
A13: 04_10_01_001_XX | B13: HFKW-23 | C13: Trifluormethan | D13: CHF3 | E13: 14800 | F13: 12400 | G13: 14800
A14: 04_10_01_002_XX | B14: HFKW-32 | C14: Difluormethan | D14: CH2F2 | E14: 675 | F14: 677 | G14: 675
A15: 04_10_01_003_XX | B15: HFKW-41 | C15: Fluormethan | D15: CH3F | E15: 92 | F15: 116 | G15: 92
A16: 04_10_01_004_XX | B16: HFKW-125 | C16: 1,1,1,2,2-Pentafluorethan | D16: CF3-CHF2 | E16: 3500 | F16: 3170 | G16: 3500
A17: 04_10_01_005_XX | B17: HFKW-134 | C17: 1,1,2,2-Tetrafluorethan | D17: CHF2-CHF2 | E17: 1100 | F17: 1120 | G17: 1100
A18: 04_10_01_006_XX | B18: HFKW-134a | C18: 1,1,1,2-Tetrafluorethan | D18: CF3-CH2F | E18: 1430 | F18: 1300 | G18: 1430
A19: 04_10_01_007_XX | B19: HFKW-143 | C19: 1,1,2-Trifluorethan | D19: CHF2-CH2F | E19: 353 | F19: 328 | G19: 353
A20: 04_10_01_008_XX | B20: HFKW-143a | C20: 1,1,1-Trifluorethan | D20: CF3-CH3 | E20: 4470 | F20: 4800 | G20: 4470
A21: 04_10_01_009_XX | B21: HFKW-152 | C21: 1,2-Difluorethan | D21: CH2F-CH2F | E21: 53 | F21: 16 | G21: 53
A22: 04_10_01_010_XX | B22: HFKW-152a | C22: 1,1-Difluorethan | D22: CHF2-CH3 | E22: 124 | F22: 138 | G22: 124
A23: 04_10_01_011_XX | B23: HFKW-161 | C23: Fluorethan | D23: CH2F-CH3 | E23: 12 | F23: 4 | G23: 12
A24: 04_10_01_012_XX | B24: HFKW-227ea | C24: 1,1,1,2,3,3,3-Heptafluorpropan | D24: CF3-CHF-CF3 | E24: 3220 | F24: 3350 | G24: 3220
... A31: 04_10_01_019_XX | B31: HFKW-43-10mee | C31: 1,1,1,2,2,3,4,5,5,5-Decafluorpentan | D31: CF3-CF2-CHF-CHF-CF3 | E31: 1640 | F31: 1650 | G31: 1640
A32: 04_10_01_020_XX | B32: HCKW-1130 (E) | C32: trans-1,2-Dichlorethen | D32: CHCl=CHCl | F32: 1
A33: 04_10_01_021_XX | B33: HFKW-1132 (E) | C33: trans-1,2-Difluorethen | D33: CHF=CHF | F33: 1 | G33: >1
A34: 04_10_01_022_XX | B34: HFKW-1132a | C34: 1,1-Difluorethen | D34: CH2=CF2 | F34: 1 | G34: 0.052
A35: 04_10_01_023_XX | B35: HFCKW-1224yd (Z) | C35: cis-1-Chlor-2,3,3,3-Tetrafluorprop-1-en | D35: CHCl=CF-CF3 (Z) | F35: 1 | G35: 0.06
A36: 04_10_01_024_XX | B36: HFCKW-1233xf | C36: 2-Chlor-3,3,3-Trifluorprop-1-en | D36: CH2=CCl-CF3 | G36: 1
A37: 04_10_01_025_XX | B37: HFCKW-1233zd (E) | C37: trans-1-Chlor-3,3,3-Trifluorprop-1-en | D37: CHCl=CH-CF3 (E) | E37: 4.5 | F37: 1 | G37: 2 | H37: AR4: [2]
A38: 04_10_01_026_XX | B38: HFKW-1234yf | C38: 2,3,3,3-Tetrafluorprop-1-en | D38: CH2=CF-CF3 | E38: 4 | F38: 1 | G38: 0.501 | H38: AR4: [2]
A39: 04_10_01_027_XX | B39: HFKW-1234ze (E) | C39: trans-1,3,3,3-Tetrafluorprop-1-en | D39: CHF=CH-CF3 (E) | E39: 7 | F39: 1 | G39: 1.37 | H39: AR4: [2]
A40: 04_10_01_028_XX | B40: HFKW-1336mzz (E) | C40: trans-1,1,1,4,4,4-Hexafluorbut-2-en | D40: CF3-CH=CH-CF3 (E) | G40: 17.9
A41: 04_10_01_029_XX | B41: HFKW-1336mzz (Z) | C41: cis-1,1,1,4,4,4-Hexafluorbut-2-en | D41: CF3-CH=CH-CF3 (Z) | E41: 9 | F41: 2 | G41: 2.08 | H41: AR4: [2]
A42: 04_10_01_030_XX | C42: 1,1,1,2,3,4,5,5,5-Nonafluor-4-trifluormethyl-pent-2-en | D42: CF3-CF=CF-CF(CF3)2 | G42: 1
A43: Perfluorierte Kohlenwasserstoffe (FKW)
A44: 04_10_02_001_XX | B44: FKW-14 | C44: Tetrafluormethan (Perfluormethan) | D44: CF4 | E44: 7390 | F44: 6630 | G44: 7380
A45: 04_10_02_002_XX | B45: FKW-116 | C45: Hexafluorethan (Perfluorethan) | D45: C2F6 | E45: 12200 | F45: 11100 | G45: 12400
A46: 04_10_02_003_XX | B46: FKW-c-216 | C46: Hexaafluorcyclopropan (Perfluorcyclopropan) | D46: c-C3F6 | E46: 17340 | F46: 9200 | G46: 9200
A47: 04_10_02_004_XX | B47: FKW-218 | C47: Oktafluorpropan (Perfluorpropan) | D47: C3F8 | E47: 8830 | F47: 8900 | G47: 9290
A48: 04_10_02_005_XX | B48: FKW-c-318 | C48: Octafluorcyclobutan (Perfluorcyclobutan) | D48: c-C4F8 | E48: 10300 | F48: 9540 | G48: 10200
...

Sheet 05_Strom
A1: Strom | C1: Scope | D1: 2 und 3
A3: Strombezug in Deutschland
A4: Anmerkung: Die Werte zum Strommix Deutschlands sollten gemäß GHG-Protocol für die ortsbasierte Berechnung der THG-Emissionen aus dem Bezug von Strom verwendet werden.
A5: ID | B5: Scope | C5: Level 1 | D5: Level 2 | E5: Einheit | F5: kg CO2e | G5: kg CO2 | H5: kg CH4 | I5: kg N2O | J5: Bezugsjahr | K5: Veröffentlichungsjahr | L5: Quelle | M5: Anmerkungen
A6: 05_20_01_001_01 | B6: Scope 2 | C6: Strom | D6: Deutscher Strommix | E6: kWh | F6: 0.3715845 | G6: 0.36338669 | H6: 0.00019444804 | I6: 1.0389679e-05 | J6: 2024 | K6: 2025 | L6: Emissionsbilanz erneuerbarer Energieträger (Lauf et al. 2026) | M6: Inklusive ~5% Übertragungsnetzverluste.
A7: 05_31_01_001_01 | B7: Scope 3 - Vorkette | C7: Strom | D7: Deutscher Strommix | E7: kWh | F7: 0.0553279 | G7: 0.032628829 | H7: 0.00065216451 | I7: 1.6748922e-05 | J7: 2024 | K7: 2025 | L7: Emissionsbilanz erneuerbarer Energieträger (Lauf et al. 2026) | M7: Inklusive ~5% Übertragungsnetzverluste.
A8: 05_32_01_001_01 | B8: Scope 3 - Gesamt | C8: Strom | D8: Deutscher Strommix | E8: kWh | F8: 0.4269124 | G8: 0.39601552 | H8: 0.00084661255 | I8: 2.7138602e-05 | J8: 2024 | K8: 2025 | L8: Emissionsbilanz erneuerbarer Energieträger (Lauf et al. 2026) | M8: Inklusive ~5% Übertragungsnetzverluste.
A10: Strom aus erneuerbaren Energieträgern
A11: Anmerkung: Biogene CO2-Emissionen aus der Verbrennung von Biomasse sind bei den entsprechenden Energieträgern nicht berücksichtigt.
A12: ID | B12: Scope | C12: Level 1 | D12: Level 2 | E12: Einheit | F12: kg CO2e | G12: kg CO2 | H12: kg CH4 | I12: kg N2O | J12: Bezugsjahr | K12: Veröffentlichungsjahr | L12: Quelle | M12: Anmerkungen
A13: 05_20_02_001_01 | B13: Scope 2 | C13: Strom | D13: Wasserkraft | E13: kWh | F13: 0 | G13: 0 | H13: 0 | I13: 0 | J13: 2024 | K13: 2025 | L13: Emissionsbilanz erneuerbarer Energieträger (Lauf et al. 2026)
A14: 05_31_02_001_01 | B14: Scope 3 - Vorkette | C14: Strom | D14: Wasserkraft | E14: kWh | F14: 0.003975047 | G14: 0.0032856108 | H14: 2.36229e-05 | I14: 1.0564141e-07 | J14: 2024 | K14: 2025 | L14: Emissionsbilanz erneuerbarer Energieträger (Lauf et al. 2026)
A15: 05_32_02_001_01 | B15: Scope 3 - Gesamt | C15: Strom | D15: Wasserkraft | E15: kWh | F15: 0.003975047 | G15: 0.0032856108 | H15: 2.36229e-05 | I15: 1.0564141e-07 | J15: 2024 | K15: 2025 | L15: Emissionsbilanz erneuerbarer Energieträger (Lauf et al. 2026)
A16: 05_20_02_002_01 | B16: Scope 2 | C16: Strom | D16: Windenergie onshore | E16: kWh | F16: 0 | G16: 0 | H16: 0 | I16: 0 | J16: 2024 | K16: 2025 | L16: Emissionsbilanz erneuerbarer Energieträger (Lauf et al. 2026)
A17: 05_31_02_002_01 | B17: Scope 3 - Vorkette | C17: Strom | D17: Windenergie onshore | E17: kWh | F17: 0.017579083 | G17: 0.017040631 | H17: 3.1273225e-05 | I17: 5.4277203e-08 | J17: 2024 | K17: 2025 | L17: Emissionsbilanz erneuerbarer Energieträger (Lauf et al. 2026)
A18: 05_32_02_002_01 | B18: Scope 3 - Gesamt | C18: Strom | D18: Windenergie onshore | E18: kWh | F18: 0.017579083 | G18: 0.017040631 | H18: 3.1273225e-05 | I18: 5.4277203e-08 | J18: 2024 | K18: 2025 | L18: Emissionsbilanz erneuerbarer Energieträger (Lauf et al. 2026)
A19: 05_20_02_003_01 | B19: Scope 2 | C19: Strom | D19: Windenergie offshore | E19: kWh | F19: 0 | G19: 0 | H19: 0 | I19: 0 | J19: 2024 | K19: 2025 | L19: Emissionsbilanz erneuerbarer Energieträger (Lauf et al. 2026)
A20: 05_31_02_003_01 | B20: Scope 3 - Vorkette | C20: Strom | D20: Windenergie offshore | E20: kWh | F20: 0.0096066033 | G20: 0.0091798255 | H20: 2.0131613e-05 | I20: 2.7138602e-08 | J20: 2024 | K20: 2025 | L20: Emissionsbilanz erneuerbarer Energieträger (Lauf et al. 2026)
A21: 05_32_02_003_01 | B21: Scope 3 - Gesamt | C21: Strom | D21: Windenergie offshore | E21: kWh | F21: 0.0096066033 | G21: 0.0091798255 | H21: 2.0131613e-05 | I21: 2.7138602e-08 | J21: 2024 | K21: 2025 | L21: Emissionsbilanz erneuerbarer Energieträger (Lauf et al. 2026)
A22: 05_20_02_004_01 | B22: Scope 2 | C22: Strom | D22: Photovoltaik | E22: kWh | F22: 0 | G22: 0 | H22: 0 | I22: 0 | J22: 2024 | K22: 2025 | L22: Emissionsbilanz erneuerbarer Energieträger (Lauf et al. 2026)
A23: 05_31_02_004_01 | B23: Scope 3 - Vorkette | C23: Strom | D23: Photovoltaik | E23: kWh | F23: 0.056492021 | G23: 0.05225666 | H23: 0.00013562661 | I23: 1.6521386e-06 | J23: 2024 | K23: 2025 | L23: Emissionsbilanz erneuerbarer Energieträger (Lauf et al. 2026)
A24: 05_32_02_004_01 | B24: Scope 3 - Gesamt | C24: Strom | D24: Photovoltaik | E24: kWh | F24: 0.056492021 | G24: 0.05225666 | H24: 0.00013562661 | I24: 1.6521386e-06 | J24: 2024 | K24: 2025 | L24: Emissionsbilanz erneuerbarer Energieträger (Lauf et al. 2026)
... A48: 05_32_02_012_01 | B48: Scope 3 - Gesamt | C48: Strom | D48: Tiefengeothermie | E48: kWh | F48: 0.14366893 | G48: 0.13341842 | H48: 0.00028265701 | I48: 8.8155225e-06 | J48: 2024 | K48: 2025 | L48: Emissionsbilanz erneuerbarer Energieträger (Lauf et al. 2026)
A50: Strom aus fossilen Energieträgern
A51: ID | B51: Scope | C51: Level 1 | D51: Level 2 | E51: Einheit | F51: kg CO2e | G51: kg CO2 | H51: kg CH4 | I51: kg N2O | J51: Bezugsjahr | K51: Veröffentlichungsjahr | L51: Quelle | M51: Anmerkungen
A52: 05_20_03_001_01 | B52: Scope 2 | C52: Strom | D52: Rohbraunkohlen | E52: kWh | F52: 1.0022244 | G52: 0.99366289 | H52: 5.7465666e-06 | I52: 3.1700452e-05 | J52: 2024 | K52: 2025 | L52: Emissionsbilanz erneuerbarer Energieträger (Lauf et al. 2026)
A53: 05_31_03_001_01 | B53: Scope 3 - Vorkette | C53: Strom | D53: Rohbraunkohlen | E53: kWh | F53: 0.026853045 | G53: 0.026204409 | H53: 1.645152e-05 | I53: 7.0941116e-07 | J53: 2024 | K53: 2025 | L53: Emissionsbilanz erneuerbarer Energieträger (Lauf et al. 2026)
A54: 05_32_03_001_01 | B54: Scope 3 - Gesamt | C54: Strom | D54: Rohbraunkohlen | E54: kWh | F54: 1.0290775 | G54: 1.0198673 | H54: 2.2198086e-05 | I54: 3.2409863e-05 | J54: 2024 | K54: 2025 | L54: Emissionsbilanz erneuerbarer Energieträger (Lauf et al. 2026)
A55: 05_20_03_002_01 | B55: Scope 2 | C55: Strom | D55: Steinkohlenkohlen | E55: kWh | F55: 0.78034728 | G55: 0.77748899 | H55: 8.260951e-06 | I55: 9.9131412e-06 | J55: 2024 | K55: 2025 | L55: Emissionsbilanz erneuerbarer Energieträger (Lauf et al. 2026)
A56: 05_31_03_002_01 | B56: Scope 3 - Vorkette | C56: Strom | D56: Steinkohlenkohlen | E56: kWh | F56: 0.097410008 | G56: 0.038408839 | H56: 0.0020929885 | I56: 1.4999692e-06 | J56: 2024 | K56: 2025 | L56: Emissionsbilanz erneuerbarer Energieträger (Lauf et al. 2026)
A57: 05_32_03_002_01 | B57: Scope 3 - Gesamt | C57: Strom | D57: Steinkohlenkohlen | E57: kWh | F57: 0.87775728 | G57: 0.81589783 | H57: 0.0021012494 | I57: 1.141311e-05 | J57: 2024 | K57: 2025 | L57: Emissionsbilanz erneuerbarer Energieträger (Lauf et al. 2026)
A58: 05_20_03_003_01 | B58: Scope 2 | C58: Strom | D58: Erdgas | E58: kWh | F58: 0.37513246 | G58: 0.35829671 | H58: 0.00052173215 | I58: 8.4047283e-06 | J58: 2024 | K58: 2025 | L58: Emissionsbilanz erneuerbarer Energieträger (Lauf et al. 2026)
A59: 05_31_03_003_01 | B59: Scope 3 - Vorkette | C59: Strom | D59: Erdgas | E59: kWh | F59: 0.062613474 | G59: 0.034191235 | H59: 0.0010081908 | I59: 7.2791587e-07 | J59: 2024 | K59: 2025 | L59: Emissionsbilanz erneuerbarer Energieträger (Lauf et al. 2026)
A60: 05_32_03_003_01 | B60: Scope 3 - Gesamt | C60: Strom | D60: Erdgas | E60: kWh | F60: 0.43774593 | G60: 0.39248794 | H60: 0.0015299229 | I60: 9.1326442e-06 | J60: 2024 | K60: 2025 | L60: Emissionsbilanz erneuerbarer Energieträger (Lauf et al. 2026)
A61: 05_20_03_004_01 | B61: Scope 2 | C61: Strom | D61: Heizöl leicht | E61: kWh | F61: 0.70237545 | G61: 0.69634609 | H61: 6.0833751e-05 | I61: 1.6324563e-05 | J61: 2024 | K61: 2025 | L61: Emissionsbilanz erneuerbarer Energieträger (Lauf et al. 2026)
A62: 05_31_03_004_01 | B62: Scope 3 - Vorkette | C62: Strom | D62: Heizöl leicht | E62: kWh | F62: 0.11478191 | G62: 0.1083088 | H62: 0.00020228301 | I62: 3.0535306e-06 | J62: 2024 | K62: 2025 | L62: Emissionsbilanz erneuerbarer Energieträger (Lauf et al. 2026)
A63: 05_32_03_004_01 | B63: Scope 3 - Gesamt | C63: Strom | D63: Heizöl leicht | E63: kWh | F63: 0.81715735 | G63: 0.80465489 | H63: 0.00026311676 | I63: 1.9378093e-05 | J63: 2024 | K63: 2025 | L63: Emissionsbilanz erneuerbarer Energieträger (Lauf et al. 2026)
A65: Weitere Energieträger
A66: ID | B66: Scope | C66: Level 1 | D66: Level 2 | E66: Einheit | F66: kg CO2e | G66: kg CO2 | H66: kg CH4 | I66: kg N2O | J66: Bezugsjahr | K66: Veröffentlichungsjahr | L66: Quelle | M66: Anmerkungen
A67: 05_20_04_001_01 | B67: Scope 2 | C67: Strom | D67: Kernenergie | E67: kWh | F67: 0 | G67: 0 | H67: 0 | I67: 0 | J67: 2024 | K67: 2025 | L67: Emissionsbilanz erneuerbarer Energieträger (Lauf et al. 2026)
...

Sheet 06_Wärme
A1: 06 Wärme | C1: Scope | D1: 2 und 3
A3: Fernwärmebezug differenziert nach hauptsächlich verwendeter Bezugsquelle
A4: Anmerkungen: Wärmenetze werden lokal betrieben und sehr unterschiedlich versorgt. Seit Anfang 2024 sind Fernwärmenetzbetreiber/-anbieter verpflichtet Emissionsfaktoren für die gelieferte Fernwärme bereitzustellen. Diese können bei Bedarf beim jeweiligen Fernwärmenetzbetreiber/-anbieter erfragt werden.
A5: ID | B5: Scope | C5: Level 1 | D5: Level 2 | E5: Level 3 | F5: Einheit | G5: kg CO2e | H5: kg CO2 | I5: kg CH4 | J5: kg N2O | K5: Bezugsjahr | L5: Veröffentlichungsjahr | M5: Quelle | N5: Anmerkungen
A6: 06_32_01_001_01 | B6: Scope 3 - Gesamt | C6: Wärme | D6: Fernwärme aus überwiegend Abfall KWK | F6: kWh | G6: 0.13 | K6: 2023 | L6: 2025 | M6: BISKO Bilanzierungs-Systematik Kommunal – Empfehlungen zur Methodik der kommunalen Treibhausgasbilanzierung für den Energie- und Verkehrssektor in Deutschland 2025 | N6: Eine Differenzierung der angegebenen BISKO-basierten Werte in unterschiedliche Treibhausgase sowie Vorketten und direkten Emissionen ist für uns leider nicht möglich.
A7: 06_32_01_002_01 | B7: Scope 3 - Gesamt | C7: Wärme | D7: Fernwärme aus überwiegend Biogas KWK | F7: kWh | G7: 0.08 | K7: 2023 | L7: 2025 | M7: BISKO Bilanzierungs-Systematik Kommunal – Empfehlungen zur Methodik der kommunalen Treibhausgasbilanzierung für den Energie- und Verkehrssektor in Deutschland 2025 | N7: Eine Differenzierung der angegebenen BISKO-basierten Werte in unterschiedliche Treibhausgase sowie Vorketten und direkten Emissionen ist für uns leider nicht möglich.
